Workbook

Sheet Inicio
B2: PRESUPUESTO FINANCIERO — PredictIT · Entrega 1
B4: Sistema de mantenimiento predictivo de equipos informáticos
B5: Trabajo Final de Ingeniería · UAI · Pettini, Patricio Ezequiel — Legajo B00072710-T1
B6: Horizonte: 2027 a 2030, mensual · Generado el 17/09/2026
B8: Las celdas amarillas son supuestos que se pueden cambiar. Todo lo demás se calcula.
B10: Contenido
B11: Hipótesis | C11: Supuestos macro, mercado meta, embudo comercial y retención
B12: Planes | C12: Líneas de servicio: precio, equipos incluidos y costo variable unitario
B13: Proyección de ventas | C13: Altas, bajas y base activa de clientes por línea, mes a mes
B14: Modelo de ingresos | C14: Facturación por línea de servicio
B15: Modelo de Egresos | C15: Consolidado de las tres estructuras de costo
B16: Costos Fijos | C16: Costos que no dependen del volumen
B17: Costos Variables | C17: Costos que se mueven con cada cliente
B18: RRHH | C18: Sueldos, cargas sociales y evolución de la plantilla
B23: Gráficos | C23: La operación en cuatro imágenes
B25: Primera entrega de negocio: llega hasta los costos de recursos humanos.

Sheet Hipótesis
A1: « Inicio
B2: HIPÓTESIS
B3: Cada variable necesita valor, fuente y justificación. Las celdas amarillas son las que se cargan a mano.
B6: Supuestos macroeconómicos
C7: 2027 | D7: 2028 | E7: 2029 | F7: 2030 | H7: Fuente y justificación
B8: Inflación anual proyectada | C8: 0.205 | D8: 0.141 | E8: 0.12 | F8: 0.1 | H8: REM del BCRA, agosto de 2026 (mediana): 20,5 % para 2027 y 14,1 % para 2028. 2029 y 2030 son extrapolación propia de esa senda: el REM llega a tres períodos anuales
B9: Tipo de cambio promedio (ARS/USD) | C9: 1800 | D9: 2050 | E9: 2300 | F9: 2530 | H9: REM del BCRA, agosto de 2026 (mediana): 1.661 $/USD en ene-27 y 1.844 a doce meses. El promedio de 2027 sale de esa senda; de 2028 en adelante acompaña a la inflación
B10: Tasa de interés de referencia | C10: 0.21 | D10: 0.16 | E10: 0.135 | F10: 0.12 | H10: REM del BCRA, agosto de 2026: TAMAR de bancos privados 23,45 % TNA a dic-26. El promedio de 2027 sale de continuar esa baja; de 2028 en adelante, extrapolación propia
B11: Puntos de precio de lista sobre la inflación | C11: 0.03 | D11: 0.03 | E11: 0.03 | F11: 0.03 | H11: Política propia: la lista se revisa por trimestre y se ubica 3 puntos por encima de la inflación proyectada, para que el precio real no se licúe
B12: Aumento anual de precios de lista | C12: =$C$8+$C$11 | D12: =$D$8+$D$11 | E12: =$E$8+$E$11 | F12: =$F$8+$F$11 | H12: Calculado: inflación del año más los puntos de arriba. Antes estaba tipeado con la cuenta ya hecha, así que cambiar la inflación no lo movía
B13: Puntos de salario sobre la inflación | C13: 0.05 | D13: 0.05 | E13: 0.05 | F13: 0.05 | H13: Política propia: 5 puntos por encima de la inflación, que es la recomposición real que viene mostrando el sector. Contrastar contra la encuesta de sueldos de Sysarmy
B14: Aumento anual de salarios | C14: =$C$8+$C$13 | D14: =$D$8+$D$13 | E14: =$E$8+$E$13 | F14: =$F$8+$F$13 | H14: Calculado: inflación del año más los puntos de arriba
B16: Prima de riesgo del proyecto sobre la inflación | C16: 0.2 | H16: Decisión propia: 20 puntos reales es lo que un proyecto de software sin historial tiene que ofrecer por encima de la inflación para justificar el capital propio
B17: Tasa de corte para el VAN | C17: =$C$8+$C$16 | H17: Calculado: inflación del año 1 más la prima de riesgo. Es el costo de oportunidad del capital propio, nominal en pesos
B18: Cuánto le gana a la tasa de referencia | C18: =$C$17-$C$10 | H18: Control: si la tasa de corte no le gana a la TAMAR del REM, el proyecto no compite contra un plazo fijo y el VAN pierde sentido
B19: Múltiplo de ingresos anuales para el valor terminal | C19: 1.5 | H19: Cuántas veces los ingresos del último año vale la cartera al cierre del horizonte. Rango de mercado para un MSP chico: 1x a 3x
B21: Mercado meta
B22: PyMEs empleadoras en el país | C22: 549100 | H22: SEPYME / CEP XXI, datos de 2023. Es la base de todo el dimensionamiento
B23: de 10 a 49 empleados | C23: 0.12 | H23: SEPYME: 85 % microempresas de 1 a 9, 12 % pequeñas de 10 a 49, 2,5 % medianas
B24: microempresas de 1 a 9 empleados | C24: 0.85 | H24: SEPYME
B25: de esas microempresas, las de 5 a 9 | C25: 0.2 | H25: Supuesto propio: el tramo de 1 a 4 concentra la mayor parte de las microempresas. Es el supuesto que más mueve el resultado y por eso está declarado aparte
B26: Participación de CABA | C26: 0.172 | H26: SEPYME, 2023: CABA reúne el 17,2 % de los establecimientos del país
B27: Participación de la provincia de Buenos Aires | C27: 0.323 | H27: SEPYME, 2023: la Provincia reúne el 32,3 %
B28: de la Provincia, lo que cae dentro del AMBA | C28: 0.75 | H28: Supuesto propio: los 24 partidos del Gran Buenos Aires concentran la mayor parte de la actividad económica de la Provincia, más que su proporción de población
B29: PyMEs de 5 a 50 empleados en AMBA | C29: =ROUND(C22*(C23+C24*C25)*(C26+C27*C28),0) | H29: Calculado: (pequeñas de 10 a 49 + el tramo de 5 a 9 de las microempresas) por la participación del AMBA. Reemplaza a los 72.000 que el plan traía sin fuente citada
B30: % con dependencia operativa alta de sus equipos | C30: 0.32 | H30: Servicios profesionales, salud, educación privada y comercio digitalizado (documento, 4.2)
B31: Mercado meta alcanzable | C31: =ROUND(C29*C30,0) | H31: Calculado
B32: Participación objetivo al año 4 | C32: 0.014 | H32: Decisión propia. Punto intermedio entre el 1,1 % que declaraba el plan y el 1,66 % que proyecta el modelo: el objetivo estaba corto y la proyección es optimista, así que se corrigen los dos hacia el medio en lugar de forzar uno para que coincida con el otro
B34: Embudo comercial | H34: Tasas de la sección 5.3.5 del documento, tomando el punto medio de cada rango
B35: Visitas web mensuales al inicio | C35: 300 | H35: Supuesto propio de arranque
B36: Crecimiento mensual de visitas | C36: 0.12 | D36: 0.08 | E36: 0.05 | F36: 0.03 | H36: Por año. Se desacelera: sostener 12 % mensual durante cuatro años multiplicaría las visitas por 200, que no es defendible
B37: Visitas a prueba gratuita iniciada | C37: 0.02 | H37: Decisión propia. Es la tasa de alta autogestionada de un producto que se prueba sin hablar con nadie; el rango del sector va de 1 % a 3 %
B38: Prueba gratuita a cliente pago | C38: 0.12 | H38: Decisión propia. Convierte menos que una prueba precedida por demostración —el documento daba 25 % a 30 %— porque nadie califica al que se registra. Lo que se gana es que el volumen deja de depender de las horas de una persona
B39: Conversión total de visita a cliente | C39: =C37*C38 | H39: Calculado. Con 1.000 visitas mensuales da del orden de 2 a 3 clientes nuevos por mes, que es lo que proyecta el documento para la Etapa E3
B41: Pilotos y canal de partners
B42: Pilotos gratuitos en la Etapa E1 | C42: 5 | H42: Documento 5.3.4
B43: % de pilotos que convierten a plan pago | C43: 0.6 | H43: Documento 5.3.4: al menos 3 de 5
B44: Mes en que convierten los pilotos | C44: 6 | H44: Cierre de los 90 días de piloto
B45: Partners activos al cierre de cada año | C45: 3 | D45: 8 | E45: 15 | F45: 25 | H45: Documento 5.3.1: 3 partners operativos al mes 12
B46: Clientes gestionados por cada partner | C46: 3 | D46: 4 | E46: 5 | F46: 5 | H46: Documento 5.3.6: mínimo de 3 clientes gestionados para acceder al descuento. Es un stock, no un flujo: un partner tiene una cartera finita
...

Sheet Planes
A1: « Inicio
B2: LÍNEAS DE SERVICIO
B3: Precios revisados en D-14, no los de la sección 5.3.6 del documento. Costos variables unitarios de la sección 6.5.3.
B6: Plan | C6: Segmento | D6: Abono mensual | E6: Equipos incluidos | F6: Equipo adicional | G6: CV infraestructura | H6: CV soporte | I6: CV servicio de IA | J6: CV total | K6: Margen de contribución
B7: Plan Inicial | C7: A | D7: 89000 | E7: 15 | F7: 4200 | G7: 3000 | H7: 4000 | I7: 1500 | J7: =SUM(G7:I7) | K7: =(D7-J7)/D7 | L7: Precio revisado (D-14). USD 49,4 por 15 equipos: USD 3,3 por equipo
B8: Plan Estándar | C8: B | D8: 239000 | E8: 50 | F8: 3500 | G8: 9000 | H8: 12000 | I8: 4000 | J8: =SUM(G8:I8) | K8: =(D8-J8)/D8 | L8: Precio revisado (D-14). USD 132,8 por 50 equipos: USD 2,7 por equipo
B9: Plan Partner | C9: C | D9: 69000 | E9: 30 | F9: 2800 | G9: 2500 | H9: 2500 | I9: 2000 | J9: =SUM(G9:I9) | K9: =(D9-J9)/D9 | L9: Precio revisado (D-14). USD 38,3 por 30 equipos: USD 1,3 por equipo. Mas bajo porque el partner aporta el canal y la primera linea de soporte
B11: El margen de contribución de cada línea lo calcula la columna de la derecha y hoy da alrededor del 90 % en las tres. Es alto, y tiene una explicación: el costo variable de un cliente de software es infraestructura y soporte, no producto. Lo que se come ese margen no es el costo variable sino la estructura fija y los sueldos, que es donde se juega el punto de equilibrio. Hasta la revisión de precios de D-14 daba entre 74 % y 76 %, que es lo que todavía dice la sección 6.5.3 del documento: hay que actualizarla.

Sheet Proyección de ventas
A1: « Inicio
B2: PROYECCIÓN DE VENTAS
B3: Clientes por línea de servicio, mes a mes. Las altas salen del embudo comercial, de la conversión de pilotos y del canal de partners; las tres fuentes se modelan por separado. | Q3: Resumen anual
Q4: Los totales de cada año, que son los que alimentan el gráfico.
Q5: Concepto | R5: 2027 | S5: 2028 | T5: 2029 | U5: 2030
Q6: Plan Inicial — Segmento A | R6: =O20 | S6: =O50 | T6: =O80 | U6: =O110
C7: 2027 | Q7: Plan Estándar — Segmento B | R7: =O26 | S7: =O56 | T7: =O86 | U7: =O116
C8: Ene | D8: Feb | E8: Mar | F8: Abr | G8: May | H8: Jun | I8: Jul | J8: Ago | K8: Sep | L8: Oct | M8: Nov | N8: Dic | O8: Total 2027 | Q8: Plan Partner — Segmento C | R8: =O30 | S8: =O60 | T8: =O90 | U8: =O120
B10: Embudo comercial
A11: EMBUDO | B11: Visitas web | C11: =Hipótesis!$C$35 | D11: =C11*(1+Hipótesis!$C$36) | E11: =D11*(1+Hipótesis!$C$36) | F11: =E11*(1+Hipótesis!$C$36) | G11: =F11*(1+Hipótesis!$C$36) | H11: =G11*(1+Hipótesis!$C$36) | I11: =H11*(1+Hipótesis!$C$36) | J11: =I11*(1+Hipótesis!$C$36) | K11: =J11*(1+Hipótesis!$C$36) | ... N11: =M11*(1+Hipótesis!$C$36) | O11: =SUM(C11:N11)
B12: Pruebas gratuitas iniciadas | C12: =C11*Hipótesis!$C$37 | D12: =D11*Hipótesis!$C$37 | E12: =E11*Hipótesis!$C$37 | F12: =F11*Hipótesis!$C$37 | G12: =G11*Hipótesis!$C$37 | H12: =H11*Hipótesis!$C$37 | I12: =I11*Hipótesis!$C$37 | J12: =J11*Hipótesis!$C$37 | ... N12: =N11*Hipótesis!$C$37 | O12: =SUM(C12:N12)
B13: Clientes nuevos por embudo directo | C13: =IF(1<Hipótesis!$C$44,0,C12*Hipótesis!$C$38) | D13: =IF(2<Hipótesis!$C$44,0,D12*Hipótesis!$C$38) | E13: =IF(3<Hipótesis!$C$44,0,E12*Hipótesis!$C$38) | F13: =IF(4<Hipótesis!$C$44,0,F12*Hipótesis!$C$38) | G13: =IF(5<Hipótesis!$C$44,0,G12*Hipótesis!$C$38) | H13: =IF(6<Hipótesis!$C$44,0,H12*Hipótesis!$C$38) | I13: =IF(7<Hipótesis!$C$44,0,I12*Hipótesis!$C$38) | J13: =IF(8<Hipótesis!$C$44,0,J12*Hipótesis!$C$38) | K13: =IF(9<Hipótesis!$C$44,0,K12*Hipótesis!$C$38) | L13: =IF(10<Hipótesis!$C$44,0,L12*Hipótesis!$C$38) | M13: =IF(11<Hipótesis!$C$44,0,M12*Hipótesis!$C$38) | N13: =IF(12<Hipótesis!$C$44,0,N12*Hipótesis!$C$38) | O13: =SUM(C13:N13)
B15: Plan Inicial — Segmento A
A16: PLAN INICIAL | B16: Base al inicio del mes | C16: 0 | D16: =C20 | E16: =D20 | F16: =E20 | G16: =F20 | H16: =G20 | I16: =H20 | J16: =I20 | K16: =J20 | ... N16: =M20
B17: Altas por embudo directo | C17: =C13 | D17: =D13 | E17: =E13 | F17: =F13 | G17: =G13 | H17: =H13 | I17: =I13 | J17: =J13 | ... N17: =N13 | O17: =SUM(C17:N17)
B18: Altas por conversión de pilotos | C18: =IF(AND(1=Hipótesis!$C$44,1=1),Hipótesis!$C$42*Hipótesis!$C$43,0) | D18: =IF(AND(2=Hipótesis!$C$44,1=1),Hipótesis!$C$42*Hipótesis!$C$43,0) | E18: =IF(AND(3=Hipótesis!$C$44,1=1),Hipótesis!$C$42*Hipótesis!$C$43,0) | F18: =IF(AND(4=Hipótesis!$C$44,1=1),Hipótesis!$C$42*Hipótesis!$C$43,0) | G18: =IF(AND(5=Hipótesis!$C$44,1=1),Hipótesis!$C$42*Hipótesis!$C$43,0) | H18: =IF(AND(6=Hipótesis!$C$44,1=1),Hipótesis!$C$42*Hipótesis!$C$43,0) | I18: =IF(AND(7=Hipótesis!$C$44,1=1),Hipótesis!$C$42*Hipótesis!$C$43,0) | J18: =IF(AND(8=Hipótesis!$C$44,1=1),Hipótesis!$C$42*Hipótesis!$C$43,0) | K18: =IF(AND(9=Hipótesis!$C$44,1=1),Hipótesis!$C$42*Hipótesis!$C$43,0) | L18: =IF(AND(10=Hipótesis!$C$44,1=1),Hipótesis!$C$42*Hipótesis!$C$43,0) | M18: =IF(AND(11=Hipótesis!$C$44,1=1),Hipótesis!$C$42*Hipótesis!$C$43,0) | N18: =IF(AND(12=Hipótesis!$C$44,1=1),Hipótesis!$C$42*Hipótesis!$C$43,0) | O18: =SUM(C18:N18)
B19: Bajas | C19: =-C16*Hipótesis!$C$50 | D19: =-D16*Hipótesis!$C$50 | E19: =-E16*Hipótesis!$C$50 | F19: =-F16*Hipótesis!$C$50 | G19: =-G16*Hipótesis!$C$50 | H19: =-H16*Hipótesis!$C$50 | I19: =-I16*Hipótesis!$C$50 | J19: =-J16*Hipótesis!$C$50 | ... N19: =-N16*Hipótesis!$C$50 | O19: =SUM(C19:N19)
B20: Base activa al cierre | C20: =SUM(C16:C19) | D20: =SUM(D16:D19) | E20: =SUM(E16:E19) | F20: =SUM(F16:F19) | G20: =SUM(G16:G19) | H20: =SUM(H16:H19) | I20: =SUM(I16:I19) | J20: =SUM(J16:J19) | ... N20: =SUM(N16:N19) | O20: =N20
B22: Plan Estándar — Segmento B | H22: Las altas del Segmento B son un supuesto directo de la hoja Hipótesis: ciclo de venta de 60 a 90 días (5.3.5) y el primer cliente en la Etapa E3. En el año 1 se reparten entre los meses 9 y 12; de ahí en adelante, a lo largo de los doce.
A23: PLAN ESTÁNDAR | B23: Base al inicio del mes | C23: 0 | D23: =C26 | E23: =D26 | F23: =E26 | G23: =F26 | H23: =G26 | I23: =H26 | J23: =I26 | K23: =J26 | ... N23: =M26
B24: Altas | C24: =IF(1<9,0,Hipótesis!$C$47/IF(1=1,4,12)) | D24: =IF(2<9,0,Hipótesis!$C$47/IF(1=1,4,12)) | E24: =IF(3<9,0,Hipótesis!$C$47/IF(1=1,4,12)) | F24: =IF(4<9,0,Hipótesis!$C$47/IF(1=1,4,12)) | G24: =IF(5<9,0,Hipótesis!$C$47/IF(1=1,4,12)) | H24: =IF(6<9,0,Hipótesis!$C$47/IF(1=1,4,12)) | I24: =IF(7<9,0,Hipótesis!$C$47/IF(1=1,4,12)) | J24: =IF(8<9,0,Hipótesis!$C$47/IF(1=1,4,12)) | K24: =IF(9<9,0,Hipótesis!$C$47/IF(1=1,4,12)) | L24: =IF(10<9,0,Hipótesis!$C$47/IF(1=1,4,12)) | M24: =IF(11<9,0,Hipótesis!$C$47/IF(1=1,4,12)) | N24: =IF(12<9,0,Hipótesis!$C$47/IF(1=1,4,12)) | O24: =SUM(C24:N24)
B25: Bajas | C25: =-C23*Hipótesis!$C$50 | D25: =-D23*Hipótesis!$C$50 | E25: =-E23*Hipótesis!$C$50 | F25: =-F23*Hipótesis!$C$50 | G25: =-G23*Hipótesis!$C$50 | H25: =-H23*Hipótesis!$C$50 | I25: =-I23*Hipótesis!$C$50 | J25: =-J23*Hipótesis!$C$50 | ... N25: =-N23*Hipótesis!$C$50 | O25: =SUM(C25:N25)
B26: Base activa al cierre | C26: =SUM(C23:C25) | D26: =SUM(D23:D25) | E26: =SUM(E23:E25) | F26: =SUM(F23:F25) | G26: =SUM(G23:G25) | H26: =SUM(H23:H25) | I26: =SUM(I23:I25) | J26: =SUM(J23:J25) | ... N26: =SUM(N23:N25) | O26: =N26
B28: Plan Partner — Segmento C | H28: La cartera del canal es un stock, no un flujo: cada partner gestiona una cantidad finita de clientes. Modelarlo como altas mensuales perpetuas haría crecer el canal sin techo.
A29: PLAN PARTNER | B29: Partners activos | C29: =ROUND(Hipótesis!$C$45*1/12,0) | D29: =ROUND(Hipótesis!$C$45*2/12,0) | E29: =ROUND(Hipótesis!$C$45*3/12,0) | F29: =ROUND(Hipótesis!$C$45*4/12,0) | G29: =ROUND(Hipótesis!$C$45*5/12,0) | H29: =ROUND(Hipótesis!$C$45*6/12,0) | I29: =ROUND(Hipótesis!$C$45*7/12,0) | J29: =ROUND(Hipótesis!$C$45*8/12,0) | K29: =ROUND(Hipótesis!$C$45*9/12,0) | L29: =ROUND(Hipótesis!$C$45*10/12,0) | M29: =ROUND(Hipótesis!$C$45*11/12,0) | N29: =ROUND(Hipótesis!$C$45*12/12,0) | O29: =N29
B30: Clientes gestionados por el canal | C30: =IF(1<Hipótesis!$C$44,0,C29*Hipótesis!$C$46) | D30: =IF(2<Hipótesis!$C$44,0,D29*Hipótesis!$C$46) | E30: =IF(3<Hipótesis!$C$44,0,E29*Hipótesis!$C$46) | F30: =IF(4<Hipótesis!$C$44,0,F29*Hipótesis!$C$46) | G30: =IF(5<Hipótesis!$C$44,0,G29*Hipótesis!$C$46) | H30: =IF(6<Hipótesis!$C$44,0,H29*Hipótesis!$C$46) | I30: =IF(7<Hipótesis!$C$44,0,I29*Hipótesis!$C$46) | J30: =IF(8<Hipótesis!$C$44,0,J29*Hipótesis!$C$46) | K30: =IF(9<Hipótesis!$C$44,0,K29*Hipótesis!$C$46) | L30: =IF(10<Hipótesis!$C$44,0,L29*Hipótesis!$C$46) | M30: =IF(11<Hipótesis!$C$44,0,M29*Hipótesis!$C$46) | N30: =IF(12<Hipótesis!$C$44,0,N29*Hipótesis!$C$46) | O30: =N30
B32: Consolidado
A33: TOTAL | B33: Clientes pagos activos | C33: =C20+C26+C30 | D33: =D20+D26+D30 | E33: =E20+E26+E30 | F33: =F20+F26+F30 | G33: =G20+G26+G30 | H33: =H20+H26+H30 | I33: =I20+I26+I30 | J33: =J20+J26+J30 | ... N33: =N20+N26+N30 | O33: =N33
B34: Equipos administrados | C34: =C20*Hipótesis!$C$51+C26*Hipótesis!$C$52+C30*Hipótesis!$C$53 | D34: =D20*Hipótesis!$C$51+D26*Hipótesis!$C$52+D30*Hipótesis!$C$53 | E34: =E20*Hipótesis!$C$51+E26*Hipótesis!$C$52+E30*Hipótesis!$C$53 | F34: =F20*Hipótesis!$C$51+F26*Hipótesis!$C$52+F30*Hipótesis!$C$53 | G34: =G20*Hipótesis!$C$51+G26*Hipótesis!$C$52+G30*Hipótesis!$C$53 | H34: =H20*Hipótesis!$C$51+H26*Hipótesis!$C$52+H30*Hipótesis!$C$53 | I34: =I20*Hipótesis!$C$51+I26*Hipótesis!$C$52+I30*Hipótesis!$C$53 | J34: =J20*Hipótesis!$C$51+J26*Hipótesis!$C$52+J30*Hipótesis!$C$53 | ... N34: =N20*Hipótesis!$C$51+N26*Hipótesis!$C$52+N30*Hipótesis!$C$53 | O34: =N34
C37: 2028
C38: Ene | D38: Feb | E38: Mar | F38: Abr | G38: May | H38: Jun | I38: Jul | J38: Ago | K38: Sep | L38: Oct | M38: Nov | N38: Dic | O38: Total 2028
B40: Embudo comercial
A41: EMBUDO | B41: Visitas web | C41: =N11*(1+Hipótesis!$D$36) | D41: =C41*(1+Hipótesis!$D$36) | E41: =D41*(1+Hipótesis!$D$36) | F41: =E41*(1+Hipótesis!$D$36) | G41: =F41*(1+Hipótesis!$D$36) | H41: =G41*(1+Hipótesis!$D$36) | I41: =H41*(1+Hipótesis!$D$36) | J41: =I41*(1+Hipótesis!$D$36) | K41: =J41*(1+Hipótesis!$D$36) | ... N41: =M41*(1+Hipótesis!$D$36) | O41: =SUM(C41:N41)
B42: Pruebas gratuitas iniciadas | C42: =C41*Hipótesis!$C$37 | D42: =D41*Hipótesis!$C$37 | E42: =E41*Hipótesis!$C$37 | F42: =F41*Hipótesis!$C$37 | G42: =G41*Hipótesis!$C$37 | H42: =H41*Hipótesis!$C$37 | I42: =I41*Hipótesis!$C$37 | J42: =J41*Hipótesis!$C$37 | ... N42: =N41*Hipótesis!$C$37 | O42: =SUM(C42:N42)
B43: Clientes nuevos por embudo directo | C43: =IF(13<Hipótesis!$C$44,0,C42*Hipótesis!$C$38) | D43: =IF(14<Hipótesis!$C$44,0,D42*Hipótesis!$C$38) | E43: =IF(15<Hipótesis!$C$44,0,E42*Hipótesis!$C$38) | F43: =IF(16<Hipótesis!$C$44,0,F42*Hipótesis!$C$38) | G43: =IF(17<Hipótesis!$C$44,0,G42*Hipótesis!$C$38) | H43: =IF(18<Hipótesis!$C$44,0,H42*Hipótesis!$C$38) | I43: =IF(19<Hipótesis!$C$44,0,I42*Hipótesis!$C$38) | J43: =IF(20<Hipótesis!$C$44,0,J42*Hipótesis!$C$38) | K43: =IF(21<Hipótesis!$C$44,0,K42*Hipótesis!$C$38) | L43: =IF(22<Hipótesis!$C$44,0,L42*Hipótesis!$C$38) | M43: =IF(23<Hipótesis!$C$44,0,M42*Hipótesis!$C$38) | N43: =IF(24<Hipótesis!$C$44,0,N42*Hipótesis!$C$38) | O43: =SUM(C43:N43)
B45: Plan Inicial — Segmento A
A46: PLAN INICIAL | B46: Base al inicio del mes | C46: =N20 | D46: =C50 | E46: =D50 | F46: =E50 | G46: =F50 | H46: =G50 | I46: =H50 | J46: =I50 | K46: =J50 | ... N46: =M50
B47: Altas por embudo directo | C47: =C43 | D47: =D43 | E47: =E43 | F47: =F43 | G47: =G43 | H47: =H43 | I47: =I43 | J47: =J43 | ... N47: =N43 | O47: =SUM(C47:N47)
B48: Altas por conversión de pilotos | C48: =IF(AND(13=Hipótesis!$C$44,2=1),Hipótesis!$C$42*Hipótesis!$C$43,0) | D48: =IF(AND(14=Hipótesis!$C$44,2=1),Hipótesis!$C$42*Hipótesis!$C$43,0) | E48: =IF(AND(15=Hipótesis!$C$44,2=1),Hipótesis!$C$42*Hipótesis!$C$43,0) | F48: =IF(AND(16=Hipótesis!$C$44,2=1),Hipótesis!$C$42*Hipótesis!$C$43,0) | G48: =IF(AND(17=Hipótesis!$C$44,2=1),Hipótesis!$C$42*Hipótesis!$C$43,0) | H48: =IF(AND(18=Hipótesis!$C$44,2=1),Hipótesis!$C$42*Hipótesis!$C$43,0) | I48: =IF(AND(19=Hipótesis!$C$44,2=1),Hipótesis!$C$42*Hipótesis!$C$43,0) | J48: =IF(AND(20=Hipótesis!$C$44,2=1),Hipótesis!$C$42*Hipótesis!$C$43,0) | K48: =IF(AND(21=Hipótesis!$C$44,2=1),Hipótesis!$C$42*Hipótesis!$C$43,0) | L48: =IF(AND(22=Hipótesis!$C$44,2=1),Hipótesis!$C$42*Hipótesis!$C$43,0) | M48: =IF(AND(23=Hipótesis!$C$44,2=1),Hipótesis!$C$42*Hipótesis!$C$43,0) | N48: =IF(AND(24=Hipótesis!$C$44,2=1),Hipótesis!$C$42*Hipótesis!$C$43,0) | O48: =SUM(C48:N48)
B49: Bajas | C49: =-C46*Hipótesis!$D$50 | D49: =-D46*Hipótesis!$D$50 | E49: =-E46*Hipótesis!$D$50 | F49: =-F46*Hipótesis!$D$50 | G49: =-G46*Hipótesis!$D$50 | H49: =-H46*Hipótesis!$D$50 | I49: =-I46*Hipótesis!$D$50 | J49: =-J46*Hipótesis!$D$50 | ... N49: =-N46*Hipótesis!$D$50 | O49: =SUM(C49:N49)
...

Sheet Modelo de ingresos
A1: « Inicio
B2: MODELO DE INGRESOS
B3: Facturación por línea: abono de la base activa más los equipos que exceden lo que incluye cada plan. Los precios se actualizan una vez por año según el supuesto de aumento de lista. | Q3: Resumen anual
Q4: Los totales de cada año, que son los que alimentan el gráfico.
Q5: Concepto | R5: 2027 | S5: 2028 | T5: 2029 | U5: 2030
Q6: Plan Inicial | R6: =O13 | S6: =O36 | T6: =O59 | U6: =O82
C7: 2027 | Q7: Plan Estándar | R7: =O18 | S7: =O41 | T7: =O64 | U7: =O87
C8: Ene | D8: Feb | E8: Mar | F8: Abr | G8: May | H8: Jun | I8: Jul | J8: Ago | K8: Sep | L8: Oct | M8: Nov | N8: Dic | O8: Total 2027 | Q8: Plan Partner | R8: =O23 | S8: =O46 | T8: =O69 | U8: =O92
B10: Plan Inicial
A11: PLAN INICIAL | B11: Ingreso por abono | C11: ='Proyección de ventas'!C20*Planes!$D$7*1 | D11: ='Proyección de ventas'!D20*Planes!$D$7*1 | E11: ='Proyección de ventas'!E20*Planes!$D$7*1 | F11: ='Proyección de ventas'!F20*Planes!$D$7*1 | G11: ='Proyección de ventas'!G20*Planes!$D$7*1 | H11: ='Proyección de ventas'!H20*Planes!$D$7*1 | I11: ='Proyección de ventas'!I20*Planes!$D$7*1 | J11: ='Proyección de ventas'!J20*Planes!$D$7*1 | ... N11: ='Proyección de ventas'!N20*Planes!$D$7*1 | O11: =SUM(C11:N11)
B12: Ingreso por equipos adicionales | C12: ='Proyección de ventas'!C20*MAX(0,Hipótesis!$C$51-Planes!$E$7)*Planes!$F$7*1 | D12: ='Proyección de ventas'!D20*MAX(0,Hipótesis!$C$51-Planes!$E$7)*Planes!$F$7*1 | E12: ='Proyección de ventas'!E20*MAX(0,Hipótesis!$C$51-Planes!$E$7)*Planes!$F$7*1 | F12: ='Proyección de ventas'!F20*MAX(0,Hipótesis!$C$51-Planes!$E$7)*Planes!$F$7*1 | G12: ='Proyección de ventas'!G20*MAX(0,Hipótesis!$C$51-Planes!$E$7)*Planes!$F$7*1 | H12: ='Proyección de ventas'!H20*MAX(0,Hipótesis!$C$51-Planes!$E$7)*Planes!$F$7*1 | I12: ='Proyección de ventas'!I20*MAX(0,Hipótesis!$C$51-Planes!$E$7)*Planes!$F$7*1 | J12: ='Proyección de ventas'!J20*MAX(0,Hipótesis!$C$51-Planes!$E$7)*Planes!$F$7*1 | ... N12: ='Proyección de ventas'!N20*MAX(0,Hipótesis!$C$51-Planes!$E$7)*Planes!$F$7*1 | O12: =SUM(C12:N12)
B13: Total de la línea | C13: =C11+C12 | D13: =D11+D12 | E13: =E11+E12 | F13: =F11+F12 | G13: =G11+G12 | H13: =H11+H12 | I13: =I11+I12 | J13: =J11+J12 | ... N13: =N11+N12 | O13: =SUM(C13:N13)
B15: Plan Estándar
A16: PLAN ESTÁNDAR | B16: Ingreso por abono | C16: ='Proyección de ventas'!C26*Planes!$D$8*1 | D16: ='Proyección de ventas'!D26*Planes!$D$8*1 | E16: ='Proyección de ventas'!E26*Planes!$D$8*1 | F16: ='Proyección de ventas'!F26*Planes!$D$8*1 | G16: ='Proyección de ventas'!G26*Planes!$D$8*1 | H16: ='Proyección de ventas'!H26*Planes!$D$8*1 | I16: ='Proyección de ventas'!I26*Planes!$D$8*1 | J16: ='Proyección de ventas'!J26*Planes!$D$8*1 | ... N16: ='Proyección de ventas'!N26*Planes!$D$8*1 | O16: =SUM(C16:N16)
B17: Ingreso por equipos adicionales | C17: ='Proyección de ventas'!C26*MAX(0,Hipótesis!$C$52-Planes!$E$8)*Planes!$F$8*1 | D17: ='Proyección de ventas'!D26*MAX(0,Hipótesis!$C$52-Planes!$E$8)*Planes!$F$8*1 | E17: ='Proyección de ventas'!E26*MAX(0,Hipótesis!$C$52-Planes!$E$8)*Planes!$F$8*1 | F17: ='Proyección de ventas'!F26*MAX(0,Hipótesis!$C$52-Planes!$E$8)*Planes!$F$8*1 | G17: ='Proyección de ventas'!G26*MAX(0,Hipótesis!$C$52-Planes!$E$8)*Planes!$F$8*1 | H17: ='Proyección de ventas'!H26*MAX(0,Hipótesis!$C$52-Planes!$E$8)*Planes!$F$8*1 | I17: ='Proyección de ventas'!I26*MAX(0,Hipótesis!$C$52-Planes!$E$8)*Planes!$F$8*1 | J17: ='Proyección de ventas'!J26*MAX(0,Hipótesis!$C$52-Planes!$E$8)*Planes!$F$8*1 | ... N17: ='Proyección de ventas'!N26*MAX(0,Hipótesis!$C$52-Planes!$E$8)*Planes!$F$8*1 | O17: =SUM(C17:N17)
B18: Total de la línea | C18: =C16+C17 | D18: =D16+D17 | E18: =E16+E17 | F18: =F16+F17 | G18: =G16+G17 | H18: =H16+H17 | I18: =I16+I17 | J18: =J16+J17 | ... N18: =N16+N17 | O18: =SUM(C18:N18)
B20: Plan Partner
A21: PLAN PARTNER | B21: Ingreso por abono | C21: ='Proyección de ventas'!C30*Planes!$D$9*1 | D21: ='Proyección de ventas'!D30*Planes!$D$9*1 | E21: ='Proyección de ventas'!E30*Planes!$D$9*1 | F21: ='Proyección de ventas'!F30*Planes!$D$9*1 | G21: ='Proyección de ventas'!G30*Planes!$D$9*1 | H21: ='Proyección de ventas'!H30*Planes!$D$9*1 | I21: ='Proyección de ventas'!I30*Planes!$D$9*1 | J21: ='Proyección de ventas'!J30*Planes!$D$9*1 | ... N21: ='Proyección de ventas'!N30*Planes!$D$9*1 | O21: =SUM(C21:N21)
B22: Ingreso por equipos adicionales | C22: ='Proyección de ventas'!C30*MAX(0,Hipótesis!$C$53-Planes!$E$9)*Planes!$F$9*1 | D22: ='Proyección de ventas'!D30*MAX(0,Hipótesis!$C$53-Planes!$E$9)*Planes!$F$9*1 | E22: ='Proyección de ventas'!E30*MAX(0,Hipótesis!$C$53-Planes!$E$9)*Planes!$F$9*1 | F22: ='Proyección de ventas'!F30*MAX(0,Hipótesis!$C$53-Planes!$E$9)*Planes!$F$9*1 | G22: ='Proyección de ventas'!G30*MAX(0,Hipótesis!$C$53-Planes!$E$9)*Planes!$F$9*1 | H22: ='Proyección de ventas'!H30*MAX(0,Hipótesis!$C$53-Planes!$E$9)*Planes!$F$9*1 | I22: ='Proyección de ventas'!I30*MAX(0,Hipótesis!$C$53-Planes!$E$9)*Planes!$F$9*1 | J22: ='Proyección de ventas'!J30*MAX(0,Hipótesis!$C$53-Planes!$E$9)*Planes!$F$9*1 | ... N22: ='Proyección de ventas'!N30*MAX(0,Hipótesis!$C$53-Planes!$E$9)*Planes!$F$9*1 | O22: =SUM(C22:N22)
B23: Total de la línea | C23: =C21+C22 | D23: =D21+D22 | E23: =E21+E22 | F23: =F21+F22 | G23: =G21+G22 | H23: =H21+H22 | I23: =I21+I22 | J23: =J21+J22 | ... N23: =N21+N22 | O23: =SUM(C23:N23)
B25: Total de ingresos
A26: TOTAL | B26: Ingresos del mes | C26: =C13+C18+C23 | D26: =D13+D18+D23 | E26: =E13+E18+E23 | F26: =F13+F18+F23 | G26: =G13+G18+G23 | H26: =H13+H18+H23 | I26: =I13+I18+I23 | J26: =J13+J18+J23 | ... N26: =N13+N18+N23 | O26: =SUM(C26:N26)
B27: Ingreso promedio por cliente | C27: =IFERROR(C26/'Proyección de ventas'!C33,0) | D27: =IFERROR(D26/'Proyección de ventas'!D33,0) | E27: =IFERROR(E26/'Proyección de ventas'!E33,0) | F27: =IFERROR(F26/'Proyección de ventas'!F33,0) | G27: =IFERROR(G26/'Proyección de ventas'!G33,0) | H27: =IFERROR(H26/'Proyección de ventas'!H33,0) | I27: =IFERROR(I26/'Proyección de ventas'!I33,0) | J27: =IFERROR(J26/'Proyección de ventas'!J33,0) | ... N27: =IFERROR(N26/'Proyección de ventas'!N33,0)
C30: 2028
C31: Ene | D31: Feb | E31: Mar | F31: Abr | G31: May | H31: Jun | I31: Jul | J31: Ago | K31: Sep | L31: Oct | M31: Nov | N31: Dic | O31: Total 2028
B33: Plan Inicial
A34: PLAN INICIAL | B34: Ingreso por abono | C34: ='Proyección de ventas'!C50*Planes!$D$7*(1+Hipótesis!$D$12) | D34: ='Proyección de ventas'!D50*Planes!$D$7*(1+Hipótesis!$D$12) | E34: ='Proyección de ventas'!E50*Planes!$D$7*(1+Hipótesis!$D$12) | F34: ='Proyección de ventas'!F50*Planes!$D$7*(1+Hipótesis!$D$12) | G34: ='Proyección de ventas'!G50*Planes!$D$7*(1+Hipótesis!$D$12) | H34: ='Proyección de ventas'!H50*Planes!$D$7*(1+Hipótesis!$D$12) | I34: ='Proyección de ventas'!I50*Planes!$D$7*(1+Hipótesis!$D$12) | J34: ='Proyección de ventas'!J50*Planes!$D$7*(1+Hipótesis!$D$12) | ... N34: ='Proyección de ventas'!N50*Planes!$D$7*(1+Hipótesis!$D$12) | O34: =SUM(C34:N34)
B35: Ingreso por equipos adicionales | C35: ='Proyección de ventas'!C50*MAX(0,Hipótesis!$D$51-Planes!$E$7)*Planes!$F$7*(1+Hipótesis!$D$12) | D35: ='Proyección de ventas'!D50*MAX(0,Hipótesis!$D$51-Planes!$E$7)*Planes!$F$7*(1+Hipótesis!$D$12) | E35: ='Proyección de ventas'!E50*MAX(0,Hipótesis!$D$51-Planes!$E$7)*Planes!$F$7*(1+Hipótesis!$D$12) | F35: ='Proyección de ventas'!F50*MAX(0,Hipótesis!$D$51-Planes!$E$7)*Planes!$F$7*(1+Hipótesis!$D$12) | G35: ='Proyección de ventas'!G50*MAX(0,Hipótesis!$D$51-Planes!$E$7)*Planes!$F$7*(1+Hipótesis!$D$12) | H35: ='Proyección de ventas'!H50*MAX(0,Hipótesis!$D$51-Planes!$E$7)*Planes!$F$7*(1+Hipótesis!$D$12) | I35: ='Proyección de ventas'!I50*MAX(0,Hipótesis!$D$51-Planes!$E$7)*Planes!$F$7*(1+Hipótesis!$D$12) | J35: ='Proyección de ventas'!J50*MAX(0,Hipótesis!$D$51-Planes!$E$7)*Planes!$F$7*(1+Hipótesis!$D$12) | ... N35: ='Proyección de ventas'!N50*MAX(0,Hipótesis!$D$51-Planes!$E$7)*Planes!$F$7*(1+Hipótesis!$D$12) | O35: =SUM(C35:N35)
B36: Total de la línea | C36: =C34+C35 | D36: =D34+D35 | E36: =E34+E35 | F36: =F34+F35 | G36: =G34+G35 | H36: =H34+H35 | I36: =I34+I35 | J36: =J34+J35 | ... N36: =N34+N35 | O36: =SUM(C36:N36)
B38: Plan Estándar
A39: PLAN ESTÁNDAR | B39: Ingreso por abono | C39: ='Proyección de ventas'!C56*Planes!$D$8*(1+Hipótesis!$D$12) | D39: ='Proyección de ventas'!D56*Planes!$D$8*(1+Hipótesis!$D$12) | E39: ='Proyección de ventas'!E56*Planes!$D$8*(1+Hipótesis!$D$12) | F39: ='Proyección de ventas'!F56*Planes!$D$8*(1+Hipótesis!$D$12) | G39: ='Proyección de ventas'!G56*Planes!$D$8*(1+Hipótesis!$D$12) | H39: ='Proyección de ventas'!H56*Planes!$D$8*(1+Hipótesis!$D$12) | I39: ='Proyección de ventas'!I56*Planes!$D$8*(1+Hipótesis!$D$12) | J39: ='Proyección de ventas'!J56*Planes!$D$8*(1+Hipótesis!$D$12) | ... N39: ='Proyección de ventas'!N56*Planes!$D$8*(1+Hipótesis!$D$12) | O39: =SUM(C39:N39)
B40: Ingreso por equipos adicionales | C40: ='Proyección de ventas'!C56*MAX(0,Hipótesis!$D$52-Planes!$E$8)*Planes!$F$8*(1+Hipótesis!$D$12) | D40: ='Proyección de ventas'!D56*MAX(0,Hipótesis!$D$52-Planes!$E$8)*Planes!$F$8*(1+Hipótesis!$D$12) | E40: ='Proyección de ventas'!E56*MAX(0,Hipótesis!$D$52-Planes!$E$8)*Planes!$F$8*(1+Hipótesis!$D$12) | F40: ='Proyección de ventas'!F56*MAX(0,Hipótesis!$D$52-Planes!$E$8)*Planes!$F$8*(1+Hipótesis!$D$12) | G40: ='Proyección de ventas'!G56*MAX(0,Hipótesis!$D$52-Planes!$E$8)*Planes!$F$8*(1+Hipótesis!$D$12) | H40: ='Proyección de ventas'!H56*MAX(0,Hipótesis!$D$52-Planes!$E$8)*Planes!$F$8*(1+Hipótesis!$D$12) | I40: ='Proyección de ventas'!I56*MAX(0,Hipótesis!$D$52-Planes!$E$8)*Planes!$F$8*(1+Hipótesis!$D$12) | J40: ='Proyección de ventas'!J56*MAX(0,Hipótesis!$D$52-Planes!$E$8)*Planes!$F$8*(1+Hipótesis!$D$12) | ... N40: ='Proyección de ventas'!N56*MAX(0,Hipótesis!$D$52-Planes!$E$8)*Planes!$F$8*(1+Hipótesis!$D$12) | O40: =SUM(C40:N40)
B41: Total de la línea | C41: =C39+C40 | D41: =D39+D40 | E41: =E39+E40 | F41: =F39+F40 | G41: =G39+G40 | H41: =H39+H40 | I41: =I39+I40 | J41: =J39+J40 | ... N41: =N39+N40 | O41: =SUM(C41:N41)
B43: Plan Partner
A44: PLAN PARTNER | B44: Ingreso por abono | C44: ='Proyección de ventas'!C60*Planes!$D$9*(1+Hipótesis!$D$12) | D44: ='Proyección de ventas'!D60*Planes!$D$9*(1+Hipótesis!$D$12) | E44: ='Proyección de ventas'!E60*Planes!$D$9*(1+Hipótesis!$D$12) | F44: ='Proyección de ventas'!F60*Planes!$D$9*(1+Hipótesis!$D$12) | G44: ='Proyección de ventas'!G60*Planes!$D$9*(1+Hipótesis!$D$12) | H44: ='Proyección de ventas'!H60*Planes!$D$9*(1+Hipótesis!$D$12) | I44: ='Proyección de ventas'!I60*Planes!$D$9*(1+Hipótesis!$D$12) | J44: ='Proyección de ventas'!J60*Planes!$D$9*(1+Hipótesis!$D$12) | ... N44: ='Proyección de ventas'!N60*Planes!$D$9*(1+Hipótesis!$D$12) | O44: =SUM(C44:N44)
B45: Ingreso por equipos adicionales | C45: ='Proyección de ventas'!C60*MAX(0,Hipótesis!$D$53-Planes!$E$9)*Planes!$F$9*(1+Hipótesis!$D$12) | D45: ='Proyección de ventas'!D60*MAX(0,Hipótesis!$D$53-Planes!$E$9)*Planes!$F$9*(1+Hipótesis!$D$12) | E45: ='Proyección de ventas'!E60*MAX(0,Hipótesis!$D$53-Planes!$E$9)*Planes!$F$9*(1+Hipótesis!$D$12) | F45: ='Proyección de ventas'!F60*MAX(0,Hipótesis!$D$53-Planes!$E$9)*Planes!$F$9*(1+Hipótesis!$D$12) | G45: ='Proyección de ventas'!G60*MAX(0,Hipótesis!$D$53-Planes!$E$9)*Planes!$F$9*(1+Hipótesis!$D$12) | H45: ='Proyección de ventas'!H60*MAX(0,Hipótesis!$D$53-Planes!$E$9)*Planes!$F$9*(1+Hipótesis!$D$12) | I45: ='Proyección de ventas'!I60*MAX(0,Hipótesis!$D$53-Planes!$E$9)*Planes!$F$9*(1+Hipótesis!$D$12) | J45: ='Proyección de ventas'!J60*MAX(0,Hipótesis!$D$53-Planes!$E$9)*Planes!$F$9*(1+Hipótesis!$D$12) | ... N45: ='Proyección de ventas'!N60*MAX(0,Hipótesis!$D$53-Planes!$E$9)*Planes!$F$9*(1+Hipótesis!$D$12) | O45: =SUM(C45:N45)
B46: Total de la línea | C46: =C44+C45 | D46: =D44+D45 | E46: =E44+E45 | F46: =F44+F45 | G46: =G44+G45 | H46: =H44+H45 | I46: =I44+I45 | J46: =J44+J45 | ... N46: =N44+N45 | O46: =SUM(C46:N46)
B48: Total de ingresos
A49: TOTAL | B49: Ingresos del mes | C49: =C36+C41+C46 | D49: =D36+D41+D46 | E49: =E36+E41+E46 | F49: =F36+F41+F46 | G49: =G36+G41+G46 | H49: =H36+H41+H46 | I49: =I36+I41+I46 | J49: =J36+J41+J46 | ... N49: =N36+N41+N46 | O49: =SUM(C49:N49)
B50: Ingreso promedio por cliente | C50: =IFERROR(C49/'Proyección de ventas'!C63,0) | D50: =IFERROR(D49/'Proyección de ventas'!D63,0) | E50: =IFERROR(E49/'Proyección de ventas'!E63,0) | F50: =IFERROR(F49/'Proyección de ventas'!F63,0) | G50: =IFERROR(G49/'Proyección de ventas'!G63,0) | H50: =IFERROR(H49/'Proyección de ventas'!H63,0) | I50: =IFERROR(I49/'Proyección de ventas'!I63,0) | J50: =IFERROR(J49/'Proyección de ventas'!J63,0) | ... N50: =IFERROR(N49/'Proyección de ventas'!N63,0)
...

Sheet Modelo de Egresos
A1: « Inicio
B2: MODELO DE EGRESOS
B3: Consolidado de las tres estructuras de costo. Cada una se carga en su propia hoja y acá sólo se suman. | Q3: Resumen anual
Q4: Los totales de cada año, que son los que alimentan el gráfico.
Q5: Concepto | R5: 2027 | S5: 2028 | T5: 2029 | U5: 2030
Q6: Costos fijos | R6: =O10 | S6: =O23 | T6: =O36 | U6: =O49
C7: 2027 | Q7: Costos variables | R7: =O11 | S7: =O24 | T7: =O37 | U7: =O50
C8: Ene | D8: Feb | E8: Mar | F8: Abr | G8: May | H8: Jun | I8: Jul | J8: Ago | K8: Sep | L8: Oct | M8: Nov | N8: Dic | O8: Total 2027 | Q8: Costos de RRHH | R8: =O12 | S8: =O25 | T8: =O38 | U8: =O51
A10: EGRESOS | B10: Costos fijos | C10: ='Costos Fijos'!C32 | D10: ='Costos Fijos'!D32 | E10: ='Costos Fijos'!E32 | F10: ='Costos Fijos'!F32 | G10: ='Costos Fijos'!G32 | H10: ='Costos Fijos'!H32 | I10: ='Costos Fijos'!I32 | J10: ='Costos Fijos'!J32 | ... N10: ='Costos Fijos'!N32 | O10: =SUM(C10:N10)
B11: Costos variables | C11: ='Costos Variables'!C14 | D11: ='Costos Variables'!D14 | E11: ='Costos Variables'!E14 | F11: ='Costos Variables'!F14 | G11: ='Costos Variables'!G14 | H11: ='Costos Variables'!H14 | I11: ='Costos Variables'!I14 | J11: ='Costos Variables'!J14 | ... N11: ='Costos Variables'!N14 | O11: =SUM(C11:N11)
B12: Costos de RRHH | C12: ='RRHH'!C48 | D12: ='RRHH'!D48 | E12: ='RRHH'!E48 | F12: ='RRHH'!F48 | G12: ='RRHH'!G48 | H12: ='RRHH'!H48 | I12: ='RRHH'!I48 | J12: ='RRHH'!J48 | ... N12: ='RRHH'!N48 | O12: =SUM(C12:N12)
B13: Total de egresos | C13: =SUM(C10:C12) | D13: =SUM(D10:D12) | E13: =SUM(E10:E12) | F13: =SUM(F10:F12) | G13: =SUM(G10:G12) | H13: =SUM(H10:H12) | I13: =SUM(I10:I12) | J13: =SUM(J10:J12) | ... N13: =SUM(N10:N12) | O13: =SUM(C13:N13)
B15: Margen
A16: MARGEN | B16: Resultado operativo (ingresos − egresos) | C16: ='Modelo de ingresos'!C26-C13 | D16: ='Modelo de ingresos'!D26-D13 | E16: ='Modelo de ingresos'!E26-E13 | F16: ='Modelo de ingresos'!F26-F13 | G16: ='Modelo de ingresos'!G26-G13 | H16: ='Modelo de ingresos'!H26-H13 | I16: ='Modelo de ingresos'!I26-I13 | J16: ='Modelo de ingresos'!J26-J13 | ... N16: ='Modelo de ingresos'!N26-N13 | O16: =SUM(C16:N16)
B17: Margen sobre ingresos | C17: =IFERROR(C16/'Modelo de ingresos'!C26,0) | D17: =IFERROR(D16/'Modelo de ingresos'!D26,0) | E17: =IFERROR(E16/'Modelo de ingresos'!E26,0) | F17: =IFERROR(F16/'Modelo de ingresos'!F26,0) | G17: =IFERROR(G16/'Modelo de ingresos'!G26,0) | H17: =IFERROR(H16/'Modelo de ingresos'!H26,0) | I17: =IFERROR(I16/'Modelo de ingresos'!I26,0) | J17: =IFERROR(J16/'Modelo de ingresos'!J26,0) | ... N17: =IFERROR(N16/'Modelo de ingresos'!N26,0)
C20: 2028
C21: Ene | D21: Feb | E21: Mar | F21: Abr | G21: May | H21: Jun | I21: Jul | J21: Ago | K21: Sep | L21: Oct | M21: Nov | N21: Dic | O21: Total 2028
A23: EGRESOS | B23: Costos fijos | C23: ='Costos Fijos'!C60 | D23: ='Costos Fijos'!D60 | E23: ='Costos Fijos'!E60 | F23: ='Costos Fijos'!F60 | G23: ='Costos Fijos'!G60 | H23: ='Costos Fijos'!H60 | I23: ='Costos Fijos'!I60 | J23: ='Costos Fijos'!J60 | ... N23: ='Costos Fijos'!N60 | O23: =SUM(C23:N23)
B24: Costos variables | C24: ='Costos Variables'!C24 | D24: ='Costos Variables'!D24 | E24: ='Costos Variables'!E24 | F24: ='Costos Variables'!F24 | G24: ='Costos Variables'!G24 | H24: ='Costos Variables'!H24 | I24: ='Costos Variables'!I24 | J24: ='Costos Variables'!J24 | ... N24: ='Costos Variables'!N24 | O24: =SUM(C24:N24)
B25: Costos de RRHH | C25: ='RRHH'!C63 | D25: ='RRHH'!D63 | E25: ='RRHH'!E63 | F25: ='RRHH'!F63 | G25: ='RRHH'!G63 | H25: ='RRHH'!H63 | I25: ='RRHH'!I63 | J25: ='RRHH'!J63 | ... N25: ='RRHH'!N63 | O25: =SUM(C25:N25)
B26: Total de egresos | C26: =SUM(C23:C25) | D26: =SUM(D23:D25) | E26: =SUM(E23:E25) | F26: =SUM(F23:F25) | G26: =SUM(G23:G25) | H26: =SUM(H23:H25) | I26: =SUM(I23:I25) | J26: =SUM(J23:J25) | ... N26: =SUM(N23:N25) | O26: =SUM(C26:N26)
B28: Margen
A29: MARGEN | B29: Resultado operativo (ingresos − egresos) | C29: ='Modelo de ingresos'!C49-C26 | D29: ='Modelo de ingresos'!D49-D26 | E29: ='Modelo de ingresos'!E49-E26 | F29: ='Modelo de ingresos'!F49-F26 | G29: ='Modelo de ingresos'!G49-G26 | H29: ='Modelo de ingresos'!H49-H26 | I29: ='Modelo de ingresos'!I49-I26 | J29: ='Modelo de ingresos'!J49-J26 | ... N29: ='Modelo de ingresos'!N49-N26 | O29: =SUM(C29:N29)
B30: Margen sobre ingresos | C30: =IFERROR(C29/'Modelo de ingresos'!C49,0) | D30: =IFERROR(D29/'Modelo de ingresos'!D49,0) | E30: =IFERROR(E29/'Modelo de ingresos'!E49,0) | F30: =IFERROR(F29/'Modelo de ingresos'!F49,0) | G30: =IFERROR(G29/'Modelo de ingresos'!G49,0) | H30: =IFERROR(H29/'Modelo de ingresos'!H49,0) | I30: =IFERROR(I29/'Modelo de ingresos'!I49,0) | J30: =IFERROR(J29/'Modelo de ingresos'!J49,0) | ... N30: =IFERROR(N29/'Modelo de ingresos'!N49,0)
C33: 2029
C34: Ene | D34: Feb | E34: Mar | F34: Abr | G34: May | H34: Jun | I34: Jul | J34: Ago | K34: Sep | L34: Oct | M34: Nov | N34: Dic | O34: Total 2029
A36: EGRESOS | B36: Costos fijos | C36: ='Costos Fijos'!C88 | D36: ='Costos Fijos'!D88 | E36: ='Costos Fijos'!E88 | F36: ='Costos Fijos'!F88 | G36: ='Costos Fijos'!G88 | H36: ='Costos Fijos'!H88 | I36: ='Costos Fijos'!I88 | J36: ='Costos Fijos'!J88 | ... N36: ='Costos Fijos'!N88 | O36: =SUM(C36:N36)
B37: Costos variables | C37: ='Costos Variables'!C34 | D37: ='Costos Variables'!D34 | E37: ='Costos Variables'!E34 | F37: ='Costos Variables'!F34 | G37: ='Costos Variables'!G34 | H37: ='Costos Variables'!H34 | I37: ='Costos Variables'!I34 | J37: ='Costos Variables'!J34 | ... N37: ='Costos Variables'!N34 | O37: =SUM(C37:N37)
B38: Costos de RRHH | C38: ='RRHH'!C78 | D38: ='RRHH'!D78 | E38: ='RRHH'!E78 | F38: ='RRHH'!F78 | G38: ='RRHH'!G78 | H38: ='RRHH'!H78 | I38: ='RRHH'!I78 | J38: ='RRHH'!J78 | ... N38: ='RRHH'!N78 | O38: =SUM(C38:N38)
B39: Total de egresos | C39: =SUM(C36:C38) | D39: =SUM(D36:D38) | E39: =SUM(E36:E38) | F39: =SUM(F36:F38) | G39: =SUM(G36:G38) | H39: =SUM(H36:H38) | I39: =SUM(I36:I38) | J39: =SUM(J36:J38) | ... N39: =SUM(N36:N38) | O39: =SUM(C39:N39)
B41: Margen
A42: MARGEN | B42: Resultado operativo (ingresos − egresos) | C42: ='Modelo de ingresos'!C72-C39 | D42: ='Modelo de ingresos'!D72-D39 | E42: ='Modelo de ingresos'!E72-E39 | F42: ='Modelo de ingresos'!F72-F39 | G42: ='Modelo de ingresos'!G72-G39 | H42: ='Modelo de ingresos'!H72-H39 | I42: ='Modelo de ingresos'!I72-I39 | J42: ='Modelo de ingresos'!J72-J39 | ... N42: ='Modelo de ingresos'!N72-N39 | O42: =SUM(C42:N42)
B43: Margen sobre ingresos | C43: =IFERROR(C42/'Modelo de ingresos'!C72,0) | D43: =IFERROR(D42/'Modelo de ingresos'!D72,0) | E43: =IFERROR(E42/'Modelo de ingresos'!E72,0) | F43: =IFERROR(F42/'Modelo de ingresos'!F72,0) | G43: =IFERROR(G42/'Modelo de ingresos'!G72,0) | H43: =IFERROR(H42/'Modelo de ingresos'!H72,0) | I43: =IFERROR(I42/'Modelo de ingresos'!I72,0) | J43: =IFERROR(J42/'Modelo de ingresos'!J72,0) | ... N43: =IFERROR(N42/'Modelo de ingresos'!N72,0)
C46: 2030
C47: Ene | D47: Feb | E47: Mar | F47: Abr | G47: May | H47: Jun | I47: Jul | J47: Ago | K47: Sep | L47: Oct | M47: Nov | N47: Dic | O47: Total 2030
A49: EGRESOS | B49: Costos fijos | C49: ='Costos Fijos'!C116 | D49: ='Costos Fijos'!D116 | E49: ='Costos Fijos'!E116 | F49: ='Costos Fijos'!F116 | G49: ='Costos Fijos'!G116 | H49: ='Costos Fijos'!H116 | I49: ='Costos Fijos'!I116 | J49: ='Costos Fijos'!J116 | ... N49: ='Costos Fijos'!N116 | O49: =SUM(C49:N49)
B50: Costos variables | C50: ='Costos Variables'!C44 | D50: ='Costos Variables'!D44 | E50: ='Costos Variables'!E44 | F50: ='Costos Variables'!F44 | G50: ='Costos Variables'!G44 | H50: ='Costos Variables'!H44 | I50: ='Costos Variables'!I44 | J50: ='Costos Variables'!J44 | ... N50: ='Costos Variables'!N44 | O50: =SUM(C50:N50)
B51: Costos de RRHH | C51: ='RRHH'!C93 | D51: ='RRHH'!D93 | E51: ='RRHH'!E93 | F51: ='RRHH'!F93 | G51: ='RRHH'!G93 | H51: ='RRHH'!H93 | I51: ='RRHH'!I93 | J51: ='RRHH'!J93 | ... N51: ='RRHH'!N93 | O51: =SUM(C51:N51)
B52: Total de egresos | C52: =SUM(C49:C51) | D52: =SUM(D49:D51) | E52: =SUM(E49:E51) | F52: =SUM(F49:F51) | G52: =SUM(G49:G51) | H52: =SUM(H49:H51) | I52: =SUM(I49:I51) | J52: =SUM(J49:J51) | ... N52: =SUM(N49:N51) | O52: =SUM(C52:N52)
B54: Margen
...

Sheet Costos Fijos
A1: « Inicio
B2: COSTOS FIJOS
B3: No dependen del volumen de clientes. Se carga el importe mensual promedio de cada año y se mantiene plano dentro del año: el salto de un año al siguiente absorbe la inflación y el crecimiento de la estructura, que en estos conceptos no es gradual sino escalonado. | Q3: Resumen anual
Q4: Los totales de cada año, que son los que alimentan el gráfico.
Q5: Concepto | R5: 2027 | S5: 2028 | T5: 2029 | U5: 2030
Q6: Total de costos fijos | R6: =O32 | S6: =O60 | T6: =O88 | U6: =O116
C7: 2027
C8: Ene | D8: Feb | E8: Mar | F8: Abr | G8: May | H8: Jun | I8: Jul | J8: Ago | K8: Sep | L8: Oct | M8: Nov | N8: Dic | O8: Total 2027
B10: Importe mensual por año (celdas de entrada)
C11: 2027 | D11: 2028 | E11: 2029 | F11: 2030 | G11: CAPEX / OPEX | H11: Origen
A12: Infraestructura | B12: Infraestructura en la nube (base) | C12: 120000 | D12: 200000 | E12: 320000 | F12: 430000 | G12: OPEX | H12: Exterior | J12: AWS o Azure. La Clase 3 lo clasifica como OPEX: no se activa, se consume
A13: Infraestructura | B13: Herramientas y licencias de desarrollo | C13: 40000 | D13: 60000 | E13: 90000 | F13: 120000 | G13: OPEX | H13: Exterior | J13: GitHub, Jira y similares. SaaS del exterior
A14: Infraestructura | B14: Herramientas de IA del equipo | C14: 90000 | D14: 140000 | E14: 200000 | F14: 260000 | G14: OPEX | H14: Exterior | J14: Claude Teams y asistentes de código, una licencia por persona de desarrollo y soporte. Es el gasto que más creció en el sector y no estaba en el modelo
A15: Comercial | B15: Marketing y contenidos | C15: 175000 | D15: 260000 | E15: 340000 | F15: 420000 | G15: OPEX | H15: Local | J15: Pauta, contenidos y herramientas de campaña
A16: Administración | B16: Estudio contable y legales | C16: 105000 | D16: 130000 | E16: 170000 | F16: 210000 | G16: OPEX | H16: Local | J16: Honorarios mensuales del estudio
A17: Operación | B17: Espacio de trabajo y telefonía | C17: 45000 | D17: 68000 | E17: 105000 | F17: 145000 | G17: OPEX | H17: Local | J17: Coworking por puesto y telefonía. No hay inmueble propio, así que el modelo no tiene impuesto inmobiliario
A18: Operación | B18: Conectividad del equipo remoto | C18: 24000 | D18: 40000 | E18: 60000 | F18: 84000 | G18: OPEX | H18: Local | J18: Reintegro de internet a cada persona: el equipo trabaja remoto y la conexión es una condición de trabajo, no un gasto personal
A19: Operación | B19: Otros gastos operativos | C19: 40000 | D19: 60000 | E19: 90000 | F19: 120000 | G19: OPEX | H19: Local | J19: Bancarios, papelería, imprevistos menores
B20: Total mensual | C20: =SUM(C12:C19) | D20: =SUM(D12:D19) | E20: =SUM(E12:E19) | F20: =SUM(F12:F19)
B21: del cual se paga al exterior | C21: =SUMIF($H$12:$H$19,"Exterior",C12:C19) | D21: =SUMIF($H$12:$H$19,"Exterior",D12:D19) | E21: =SUMIF($H$12:$H$19,"Exterior",E12:E19) | F21: =SUMIF($H$12:$H$19,"Exterior",F12:F19) | J21: Servicios digitales importados: nube, licencias y herramientas de IA. La hoja Impuestos les aplica el IVA acrecentado y la retención a beneficiarios del exterior
B23: Desarrollo mensual
A24: Infraestructura | B24: Infraestructura en la nube (base) | C24: =$C$12 | D24: =$C$12 | E24: =$C$12 | F24: =$C$12 | G24: =$C$12 | H24: =$C$12 | I24: =$C$12 | J24: =$C$12 | ... N24: =$C$12 | O24: =SUM(C24:N24)
A25: Infraestructura | B25: Herramientas y licencias de desarrollo | C25: =$C$13 | D25: =$C$13 | E25: =$C$13 | F25: =$C$13 | G25: =$C$13 | H25: =$C$13 | I25: =$C$13 | J25: =$C$13 | ... N25: =$C$13 | O25: =SUM(C25:N25)
A26: Infraestructura | B26: Herramientas de IA del equipo | C26: =$C$14 | D26: =$C$14 | E26: =$C$14 | F26: =$C$14 | G26: =$C$14 | H26: =$C$14 | I26: =$C$14 | J26: =$C$14 | ... N26: =$C$14 | O26: =SUM(C26:N26)
A27: Comercial | B27: Marketing y contenidos | C27: =$C$15 | D27: =$C$15 | E27: =$C$15 | F27: =$C$15 | G27: =$C$15 | H27: =$C$15 | I27: =$C$15 | J27: =$C$15 | ... N27: =$C$15 | O27: =SUM(C27:N27)
A28: Administración | B28: Estudio contable y legales | C28: =$C$16 | D28: =$C$16 | E28: =$C$16 | F28: =$C$16 | G28: =$C$16 | H28: =$C$16 | I28: =$C$16 | J28: =$C$16 | ... N28: =$C$16 | O28: =SUM(C28:N28)
A29: Operación | B29: Espacio de trabajo y telefonía | C29: =$C$17 | D29: =$C$17 | E29: =$C$17 | F29: =$C$17 | G29: =$C$17 | H29: =$C$17 | I29: =$C$17 | J29: =$C$17 | ... N29: =$C$17 | O29: =SUM(C29:N29)
A30: Operación | B30: Conectividad del equipo remoto | C30: =$C$18 | D30: =$C$18 | E30: =$C$18 | F30: =$C$18 | G30: =$C$18 | H30: =$C$18 | I30: =$C$18 | J30: =$C$18 | ... N30: =$C$18 | O30: =SUM(C30:N30)
A31: Operación | B31: Otros gastos operativos | C31: =$C$19 | D31: =$C$19 | E31: =$C$19 | F31: =$C$19 | G31: =$C$19 | H31: =$C$19 | I31: =$C$19 | J31: =$C$19 | ... N31: =$C$19 | O31: =SUM(C31:N31)
A32: COSTOS FIJOS | B32: Total de costos fijos | C32: =SUM(C24:C31) | D32: =SUM(D24:D31) | E32: =SUM(E24:E31) | F32: =SUM(F24:F31) | G32: =SUM(G24:G31) | H32: =SUM(H24:H31) | I32: =SUM(I24:I31) | J32: =SUM(J24:J31) | ... N32: =SUM(N24:N31) | O32: =SUM(C32:N32)
C35: 2028
C36: Ene | D36: Feb | E36: Mar | F36: Abr | G36: May | H36: Jun | I36: Jul | J36: Ago | K36: Sep | L36: Oct | M36: Nov | N36: Dic | O36: Total 2028
B38: Importe mensual por año (celdas de entrada)
A40: Infraestructura | B40: Infraestructura en la nube (base)
A41: Infraestructura | B41: Herramientas y licencias de desarrollo
A42: Infraestructura | B42: Herramientas de IA del equipo
A43: Comercial | B43: Marketing y contenidos
A44: Administración | B44: Estudio contable y legales
A45: Operación | B45: Espacio de trabajo y telefonía
A46: Operación | B46: Conectividad del equipo remoto
...

Sheet Costos Variables
A1: « Inicio
B2: COSTOS VARIABLES
B3: Se mueven con cada cliente. Los importes unitarios salen de la sección 6.5.3 del documento y se toman de la hoja Planes, para que no haya dos versiones del mismo número. Cada concepto se ajusta por el índice que le corresponde: los dos que se pagan en dólares siguen al tipo de cambio y el soporte, que es trabajo local, sigue a los salarios. | Q3: Resumen anual
Q4: Los totales de cada año, que son los que alimentan el gráfico.
Q5: Concepto | R5: 2027 | S5: 2028 | T5: 2029 | U5: 2030
Q6: Infraestructura en la nube | R6: =O11 | S6: =O21 | T6: =O31 | U6: =O41
C7: 2027 | Q7: Soporte | R7: =O12 | S7: =O22 | T7: =O32 | U7: =O42
C8: Ene | D8: Feb | E8: Mar | F8: Abr | G8: May | H8: Jun | I8: Jul | J8: Ago | K8: Sep | L8: Oct | M8: Nov | N8: Dic | O8: Total 2027 | Q8: Servicio externo de IA | R8: =O13 | S8: =O23 | T8: =O33 | U8: =O43
B10: Por concepto
A11: VARIABLES | B11: Infraestructura por cliente (sigue al dólar) | C11: =('Proyección de ventas'!C20*Planes!$G$7+'Proyección de ventas'!C26*Planes!$G$8+'Proyección de ventas'!C30*Planes!$G$9)*1 | D11: =('Proyección de ventas'!D20*Planes!$G$7+'Proyección de ventas'!D26*Planes!$G$8+'Proyección de ventas'!D30*Planes!$G$9)*1 | E11: =('Proyección de ventas'!E20*Planes!$G$7+'Proyección de ventas'!E26*Planes!$G$8+'Proyección de ventas'!E30*Planes!$G$9)*1 | F11: =('Proyección de ventas'!F20*Planes!$G$7+'Proyección de ventas'!F26*Planes!$G$8+'Proyección de ventas'!F30*Planes!$G$9)*1 | G11: =('Proyección de ventas'!G20*Planes!$G$7+'Proyección de ventas'!G26*Planes!$G$8+'Proyección de ventas'!G30*Planes!$G$9)*1 | H11: =('Proyección de ventas'!H20*Planes!$G$7+'Proyección de ventas'!H26*Planes!$G$8+'Proyección de ventas'!H30*Planes!$G$9)*1 | I11: =('Proyección de ventas'!I20*Planes!$G$7+'Proyección de ventas'!I26*Planes!$G$8+'Proyección de ventas'!I30*Planes!$G$9)*1 | J11: =('Proyección de ventas'!J20*Planes!$G$7+'Proyección de ventas'!J26*Planes!$G$8+'Proyección de ventas'!J30*Planes!$G$9)*1 | ... N11: =('Proyección de ventas'!N20*Planes!$G$7+'Proyección de ventas'!N26*Planes!$G$8+'Proyección de ventas'!N30*Planes!$G$9)*1 | O11: =SUM(C11:N11)
B12: Soporte y onboarding por cliente (sigue a los salarios) | C12: =('Proyección de ventas'!C20*Planes!$H$7+'Proyección de ventas'!C26*Planes!$H$8+'Proyección de ventas'!C30*Planes!$H$9)*1 | D12: =('Proyección de ventas'!D20*Planes!$H$7+'Proyección de ventas'!D26*Planes!$H$8+'Proyección de ventas'!D30*Planes!$H$9)*1 | E12: =('Proyección de ventas'!E20*Planes!$H$7+'Proyección de ventas'!E26*Planes!$H$8+'Proyección de ventas'!E30*Planes!$H$9)*1 | F12: =('Proyección de ventas'!F20*Planes!$H$7+'Proyección de ventas'!F26*Planes!$H$8+'Proyección de ventas'!F30*Planes!$H$9)*1 | G12: =('Proyección de ventas'!G20*Planes!$H$7+'Proyección de ventas'!G26*Planes!$H$8+'Proyección de ventas'!G30*Planes!$H$9)*1 | H12: =('Proyección de ventas'!H20*Planes!$H$7+'Proyección de ventas'!H26*Planes!$H$8+'Proyección de ventas'!H30*Planes!$H$9)*1 | I12: =('Proyección de ventas'!I20*Planes!$H$7+'Proyección de ventas'!I26*Planes!$H$8+'Proyección de ventas'!I30*Planes!$H$9)*1 | J12: =('Proyección de ventas'!J20*Planes!$H$7+'Proyección de ventas'!J26*Planes!$H$8+'Proyección de ventas'!J30*Planes!$H$9)*1 | ... N12: =('Proyección de ventas'!N20*Planes!$H$7+'Proyección de ventas'!N26*Planes!$H$8+'Proyección de ventas'!N30*Planes!$H$9)*1 | O12: =SUM(C12:N12)
B13: Servicio externo de inteligencia artificial (sigue al dólar) | C13: =('Proyección de ventas'!C20*Planes!$I$7+'Proyección de ventas'!C26*Planes!$I$8+'Proyección de ventas'!C30*Planes!$I$9)*1 | D13: =('Proyección de ventas'!D20*Planes!$I$7+'Proyección de ventas'!D26*Planes!$I$8+'Proyección de ventas'!D30*Planes!$I$9)*1 | E13: =('Proyección de ventas'!E20*Planes!$I$7+'Proyección de ventas'!E26*Planes!$I$8+'Proyección de ventas'!E30*Planes!$I$9)*1 | F13: =('Proyección de ventas'!F20*Planes!$I$7+'Proyección de ventas'!F26*Planes!$I$8+'Proyección de ventas'!F30*Planes!$I$9)*1 | G13: =('Proyección de ventas'!G20*Planes!$I$7+'Proyección de ventas'!G26*Planes!$I$8+'Proyección de ventas'!G30*Planes!$I$9)*1 | H13: =('Proyección de ventas'!H20*Planes!$I$7+'Proyección de ventas'!H26*Planes!$I$8+'Proyección de ventas'!H30*Planes!$I$9)*1 | I13: =('Proyección de ventas'!I20*Planes!$I$7+'Proyección de ventas'!I26*Planes!$I$8+'Proyección de ventas'!I30*Planes!$I$9)*1 | J13: =('Proyección de ventas'!J20*Planes!$I$7+'Proyección de ventas'!J26*Planes!$I$8+'Proyección de ventas'!J30*Planes!$I$9)*1 | ... N13: =('Proyección de ventas'!N20*Planes!$I$7+'Proyección de ventas'!N26*Planes!$I$8+'Proyección de ventas'!N30*Planes!$I$9)*1 | O13: =SUM(C13:N13)
B14: Total de costos variables | C14: =SUM(C11:C13) | D14: =SUM(D11:D13) | E14: =SUM(E11:E13) | F14: =SUM(F11:F13) | G14: =SUM(G11:G13) | H14: =SUM(H11:H13) | I14: =SUM(I11:I13) | J14: =SUM(J11:J13) | ... N14: =SUM(N11:N13) | O14: =SUM(C14:N14)
C17: 2028
C18: Ene | D18: Feb | E18: Mar | F18: Abr | G18: May | H18: Jun | I18: Jul | J18: Ago | K18: Sep | L18: Oct | M18: Nov | N18: Dic | O18: Total 2028
B20: Por concepto
A21: VARIABLES | B21: Infraestructura por cliente (sigue al dólar) | C21: =('Proyección de ventas'!C50*Planes!$G$7+'Proyección de ventas'!C56*Planes!$G$8+'Proyección de ventas'!C60*Planes!$G$9)*Hipótesis!$D$9/Hipótesis!$C$9 | D21: =('Proyección de ventas'!D50*Planes!$G$7+'Proyección de ventas'!D56*Planes!$G$8+'Proyección de ventas'!D60*Planes!$G$9)*Hipótesis!$D$9/Hipótesis!$C$9 | E21: =('Proyección de ventas'!E50*Planes!$G$7+'Proyección de ventas'!E56*Planes!$G$8+'Proyección de ventas'!E60*Planes!$G$9)*Hipótesis!$D$9/Hipótesis!$C$9 | F21: =('Proyección de ventas'!F50*Planes!$G$7+'Proyección de ventas'!F56*Planes!$G$8+'Proyección de ventas'!F60*Planes!$G$9)*Hipótesis!$D$9/Hipótesis!$C$9 | G21: =('Proyección de ventas'!G50*Planes!$G$7+'Proyección de ventas'!G56*Planes!$G$8+'Proyección de ventas'!G60*Planes!$G$9)*Hipótesis!$D$9/Hipótesis!$C$9 | H21: =('Proyección de ventas'!H50*Planes!$G$7+'Proyección de ventas'!H56*Planes!$G$8+'Proyección de ventas'!H60*Planes!$G$9)*Hipótesis!$D$9/Hipótesis!$C$9 | I21: =('Proyección de ventas'!I50*Planes!$G$7+'Proyección de ventas'!I56*Planes!$G$8+'Proyección de ventas'!I60*Planes!$G$9)*Hipótesis!$D$9/Hipótesis!$C$9 | J21: =('Proyección de ventas'!J50*Planes!$G$7+'Proyección de ventas'!J56*Planes!$G$8+'Proyección de ventas'!J60*Planes!$G$9)*Hipótesis!$D$9/Hipótesis!$C$9 | ... N21: =('Proyección de ventas'!N50*Planes!$G$7+'Proyección de ventas'!N56*Planes!$G$8+'Proyección de ventas'!N60*Planes!$G$9)*Hipótesis!$D$9/Hipótesis!$C$9 | O21: =SUM(C21:N21)
B22: Soporte y onboarding por cliente (sigue a los salarios) | C22: =('Proyección de ventas'!C50*Planes!$H$7+'Proyección de ventas'!C56*Planes!$H$8+'Proyección de ventas'!C60*Planes!$H$9)*(1+Hipótesis!$D$14) | D22: =('Proyección de ventas'!D50*Planes!$H$7+'Proyección de ventas'!D56*Planes!$H$8+'Proyección de ventas'!D60*Planes!$H$9)*(1+Hipótesis!$D$14) | E22: =('Proyección de ventas'!E50*Planes!$H$7+'Proyección de ventas'!E56*Planes!$H$8+'Proyección de ventas'!E60*Planes!$H$9)*(1+Hipótesis!$D$14) | F22: =('Proyección de ventas'!F50*Planes!$H$7+'Proyección de ventas'!F56*Planes!$H$8+'Proyección de ventas'!F60*Planes!$H$9)*(1+Hipótesis!$D$14) | G22: =('Proyección de ventas'!G50*Planes!$H$7+'Proyección de ventas'!G56*Planes!$H$8+'Proyección de ventas'!G60*Planes!$H$9)*(1+Hipótesis!$D$14) | H22: =('Proyección de ventas'!H50*Planes!$H$7+'Proyección de ventas'!H56*Planes!$H$8+'Proyección de ventas'!H60*Planes!$H$9)*(1+Hipótesis!$D$14) | I22: =('Proyección de ventas'!I50*Planes!$H$7+'Proyección de ventas'!I56*Planes!$H$8+'Proyección de ventas'!I60*Planes!$H$9)*(1+Hipótesis!$D$14) | J22: =('Proyección de ventas'!J50*Planes!$H$7+'Proyección de ventas'!J56*Planes!$H$8+'Proyección de ventas'!J60*Planes!$H$9)*(1+Hipótesis!$D$14) | ... N22: =('Proyección de ventas'!N50*Planes!$H$7+'Proyección de ventas'!N56*Planes!$H$8+'Proyección de ventas'!N60*Planes!$H$9)*(1+Hipótesis!$D$14) | O22: =SUM(C22:N22)
B23: Servicio externo de inteligencia artificial (sigue al dólar) | C23: =('Proyección de ventas'!C50*Planes!$I$7+'Proyección de ventas'!C56*Planes!$I$8+'Proyección de ventas'!C60*Planes!$I$9)*Hipótesis!$D$9/Hipótesis!$C$9 | D23: =('Proyección de ventas'!D50*Planes!$I$7+'Proyección de ventas'!D56*Planes!$I$8+'Proyección de ventas'!D60*Planes!$I$9)*Hipótesis!$D$9/Hipótesis!$C$9 | E23: =('Proyección de ventas'!E50*Planes!$I$7+'Proyección de ventas'!E56*Planes!$I$8+'Proyección de ventas'!E60*Planes!$I$9)*Hipótesis!$D$9/Hipótesis!$C$9 | F23: =('Proyección de ventas'!F50*Planes!$I$7+'Proyección de ventas'!F56*Planes!$I$8+'Proyección de ventas'!F60*Planes!$I$9)*Hipótesis!$D$9/Hipótesis!$C$9 | G23: =('Proyección de ventas'!G50*Planes!$I$7+'Proyección de ventas'!G56*Planes!$I$8+'Proyección de ventas'!G60*Planes!$I$9)*Hipótesis!$D$9/Hipótesis!$C$9 | H23: =('Proyección de ventas'!H50*Planes!$I$7+'Proyección de ventas'!H56*Planes!$I$8+'Proyección de ventas'!H60*Planes!$I$9)*Hipótesis!$D$9/Hipótesis!$C$9 | I23: =('Proyección de ventas'!I50*Planes!$I$7+'Proyección de ventas'!I56*Planes!$I$8+'Proyección de ventas'!I60*Planes!$I$9)*Hipótesis!$D$9/Hipótesis!$C$9 | J23: =('Proyección de ventas'!J50*Planes!$I$7+'Proyección de ventas'!J56*Planes!$I$8+'Proyección de ventas'!J60*Planes!$I$9)*Hipótesis!$D$9/Hipótesis!$C$9 | ... N23: =('Proyección de ventas'!N50*Planes!$I$7+'Proyección de ventas'!N56*Planes!$I$8+'Proyección de ventas'!N60*Planes!$I$9)*Hipótesis!$D$9/Hipótesis!$C$9 | O23: =SUM(C23:N23)
B24: Total de costos variables | C24: =SUM(C21:C23) | D24: =SUM(D21:D23) | E24: =SUM(E21:E23) | F24: =SUM(F21:F23) | G24: =SUM(G21:G23) | H24: =SUM(H21:H23) | I24: =SUM(I21:I23) | J24: =SUM(J21:J23) | ... N24: =SUM(N21:N23) | O24: =SUM(C24:N24)
C27: 2029
C28: Ene | D28: Feb | E28: Mar | F28: Abr | G28: May | H28: Jun | I28: Jul | J28: Ago | K28: Sep | L28: Oct | M28: Nov | N28: Dic | O28: Total 2029
B30: Por concepto
A31: VARIABLES | B31: Infraestructura por cliente (sigue al dólar) | C31: =('Proyección de ventas'!C80*Planes!$G$7+'Proyección de ventas'!C86*Planes!$G$8+'Proyección de ventas'!C90*Planes!$G$9)*Hipótesis!$E$9/Hipótesis!$C$9 | D31: =('Proyección de ventas'!D80*Planes!$G$7+'Proyección de ventas'!D86*Planes!$G$8+'Proyección de ventas'!D90*Planes!$G$9)*Hipótesis!$E$9/Hipótesis!$C$9 | E31: =('Proyección de ventas'!E80*Planes!$G$7+'Proyección de ventas'!E86*Planes!$G$8+'Proyección de ventas'!E90*Planes!$G$9)*Hipótesis!$E$9/Hipótesis!$C$9 | F31: =('Proyección de ventas'!F80*Planes!$G$7+'Proyección de ventas'!F86*Planes!$G$8+'Proyección de ventas'!F90*Planes!$G$9)*Hipótesis!$E$9/Hipótesis!$C$9 | G31: =('Proyección de ventas'!G80*Planes!$G$7+'Proyección de ventas'!G86*Planes!$G$8+'Proyección de ventas'!G90*Planes!$G$9)*Hipótesis!$E$9/Hipótesis!$C$9 | H31: =('Proyección de ventas'!H80*Planes!$G$7+'Proyección de ventas'!H86*Planes!$G$8+'Proyección de ventas'!H90*Planes!$G$9)*Hipótesis!$E$9/Hipótesis!$C$9 | I31: =('Proyección de ventas'!I80*Planes!$G$7+'Proyección de ventas'!I86*Planes!$G$8+'Proyección de ventas'!I90*Planes!$G$9)*Hipótesis!$E$9/Hipótesis!$C$9 | J31: =('Proyección de ventas'!J80*Planes!$G$7+'Proyección de ventas'!J86*Planes!$G$8+'Proyección de ventas'!J90*Planes!$G$9)*Hipótesis!$E$9/Hipótesis!$C$9 | ... N31: =('Proyección de ventas'!N80*Planes!$G$7+'Proyección de ventas'!N86*Planes!$G$8+'Proyección de ventas'!N90*Planes!$G$9)*Hipótesis!$E$9/Hipótesis!$C$9 | O31: =SUM(C31:N31)
B32: Soporte y onboarding por cliente (sigue a los salarios) | C32: =('Proyección de ventas'!C80*Planes!$H$7+'Proyección de ventas'!C86*Planes!$H$8+'Proyección de ventas'!C90*Planes!$H$9)*(1+Hipótesis!$D$14)*(1+Hipótesis!$E$14) | D32: =('Proyección de ventas'!D80*Planes!$H$7+'Proyección de ventas'!D86*Planes!$H$8+'Proyección de ventas'!D90*Planes!$H$9)*(1+Hipótesis!$D$14)*(1+Hipótesis!$E$14) | E32: =('Proyección de ventas'!E80*Planes!$H$7+'Proyección de ventas'!E86*Planes!$H$8+'Proyección de ventas'!E90*Planes!$H$9)*(1+Hipótesis!$D$14)*(1+Hipótesis!$E$14) | F32: =('Proyección de ventas'!F80*Planes!$H$7+'Proyección de ventas'!F86*Planes!$H$8+'Proyección de ventas'!F90*Planes!$H$9)*(1+Hipótesis!$D$14)*(1+Hipótesis!$E$14) | G32: =('Proyección de ventas'!G80*Planes!$H$7+'Proyección de ventas'!G86*Planes!$H$8+'Proyección de ventas'!G90*Planes!$H$9)*(1+Hipótesis!$D$14)*(1+Hipótesis!$E$14) | H32: =('Proyección de ventas'!H80*Planes!$H$7+'Proyección de ventas'!H86*Planes!$H$8+'Proyección de ventas'!H90*Planes!$H$9)*(1+Hipótesis!$D$14)*(1+Hipótesis!$E$14) | I32: =('Proyección de ventas'!I80*Planes!$H$7+'Proyección de ventas'!I86*Planes!$H$8+'Proyección de ventas'!I90*Planes!$H$9)*(1+Hipótesis!$D$14)*(1+Hipótesis!$E$14) | J32: =('Proyección de ventas'!J80*Planes!$H$7+'Proyección de ventas'!J86*Planes!$H$8+'Proyección de ventas'!J90*Planes!$H$9)*(1+Hipótesis!$D$14)*(1+Hipótesis!$E$14) | ... N32: =('Proyección de ventas'!N80*Planes!$H$7+'Proyección de ventas'!N86*Planes!$H$8+'Proyección de ventas'!N90*Planes!$H$9)*(1+Hipótesis!$D$14)*(1+Hipótesis!$E$14) | O32: =SUM(C32:N32)
