Workbook

Sheet Inicio
B2: PRESUPUESTO FINANCIERO — PredictIT · Entrega 1
B4: Sistema de mantenimiento predictivo de equipos informáticos
B5: Trabajo Final de Ingeniería · UAI · Pettini, Patricio Ezequiel — Legajo B00072710-T1
B6: Horizonte: 2027 a 2030, mensual · Generado el 07/09/2026
B8: Las celdas amarillas son supuestos que se pueden cambiar. Todo lo demás se calcula.
B10: Contenido
B11: Hipótesis | C11: Supuestos macro, mercado meta, embudo comercial y retención
B12: Planes | C12: Líneas de servicio: precio, equipos incluidos y costo variable unitario
B13: Proyección de ventas | C13: Altas, bajas y base activa de clientes por línea, mes a mes
B14: Modelo de ingresos | C14: Facturación por línea de servicio
B15: Modelo de Egresos | C15: Consolidado de las tres estructuras de costo
B16: Costos Fijos | C16: Costos que no dependen del volumen
B17: Costos Variables | C17: Costos que se mueven con cada cliente
B18: RRHH | C18: Sueldos, cargas sociales y evolución de la plantilla
B20: Primera entrega de negocio: llega hasta los costos de recursos humanos.

Sheet Hipótesis
A1: « Inicio
B2: HIPÓTESIS
B3: Cada variable necesita valor, fuente y justificación. Las celdas amarillas son las que se cargan a mano.
B6: Supuestos macroeconómicos
C7: 2027 | D7: 2028 | E7: 2029 | F7: 2030 | H7: Fuente y justificación
B8: Inflación anual proyectada | C8: 0.35 | D8: 0.25 | E8: 0.18 | F8: 0.15 | H8: PROVISORIO — reemplazar por el REM del BCRA citando la fecha del informe
B9: Tipo de cambio promedio (ARS/USD) | C9: 1900 | D9: 2350 | E9: 2750 | F9: 3150 | H9: PROVISORIO — reemplazar por el REM del BCRA. Afecta la infraestructura en la nube y el servicio de IA
B10: Tasa de interés de referencia | C10: 0.3 | D10: 0.22 | E10: 0.17 | F10: 0.14 | H10: PROVISORIO — tasa de política monetaria del BCRA
B11: Aumento anual de precios de lista | C11: 0.38 | D11: 0.27 | E11: 0.2 | F11: 0.16 | H11: Política propia: revisión trimestral (documento, 5.3.6). Va apenas arriba de la inflación
B12: Aumento anual de salarios | C12: 0.4 | D12: 0.3 | E12: 0.22 | F12: 0.18 | H12: Paritarias del sector. Es el costo que más pesa a partir de la Etapa E3
B14: Tasa de corte para el VAN | C14: 0.6 | H14: PROVISORIO — costo de oportunidad del capital propio, nominal en pesos. Debe superar a la tasa libre de riesgo más la prima por riesgo del proyecto
B15: Múltiplo de ingresos anuales para el valor terminal | C15: 1.5 | H15: Cuántas veces los ingresos del último año vale la cartera al cierre del horizonte. Rango de mercado para un MSP chico: 1x a 3x
B17: Mercado meta
B18: PyMEs de 5 a 50 empleados en AMBA | C18: 72000 | H18: PROVISORIO — reemplazar por Fundación Observatorio PyME / censo. Es el universo del Segmento A
B19: % con dependencia operativa alta de sus equipos | C19: 0.32 | H19: Servicios profesionales, salud, educación privada y comercio digitalizado (documento, 4.2)
B20: Mercado meta alcanzable | C20: =C18*C19 | H20: Calculado
B21: Participación objetivo al año 4 | C21: 0.011 | H21: Objetivo propio. Contrastar contra los 220 clientes del punto de equilibrio (documento, 7.7)
B23: Embudo comercial | H23: Tasas de la sección 5.3.5 del documento, tomando el punto medio de cada rango
B24: Visitas web mensuales al inicio | C24: 300 | H24: Supuesto propio de arranque
B25: Crecimiento mensual de visitas | C25: 0.12 | D25: 0.08 | E25: 0.05 | F25: 0.03 | H25: Por año. Se desacelera: sostener 12 % mensual durante cuatro años multiplicaría las visitas por 200, que no es defendible
B26: Visitas → leads | C26: 0.04 | H26: Documento 5.3.5: rango 3 % a 5 %
B27: Leads → demos calificadas | C27: 0.4 | H27: Documento 5.3.5: rango 35 % a 45 %
B28: Demos → pruebas gratuitas | C28: 0.6 | H28: Documento 5.3.5: rango 55 % a 65 %
B29: Pruebas → cliente pago | C29: 0.275 | H29: Documento 5.3.5: rango 25 % a 30 % para el Segmento A
B30: Conversión total visita → cliente | C30: =C26*C27*C28*C29 | H30: Calculado. Con 1.000 visitas mensuales da del orden de 2 a 3 clientes nuevos por mes, que es lo que proyecta el documento para la Etapa E3
B32: Pilotos y canal de partners
B33: Pilotos gratuitos en la Etapa E1 | C33: 5 | H33: Documento 5.3.4
B34: % de pilotos que convierten a plan pago | C34: 0.6 | H34: Documento 5.3.4: al menos 3 de 5
B35: Mes en que convierten los pilotos | C35: 6 | H35: Cierre de los 90 días de piloto
B36: Partners activos al cierre de cada año | C36: 3 | D36: 8 | E36: 15 | F36: 25 | H36: Documento 5.3.1: 3 partners operativos al mes 12
B37: Clientes gestionados por cada partner | C37: 3 | D37: 4 | E37: 5 | F37: 5 | H37: Documento 5.3.6: mínimo de 3 clientes gestionados para acceder al descuento. Es un stock, no un flujo: un partner tiene una cartera finita
B39: Retención y parque administrado
B40: Baja mensual de clientes | C40: 0.07 | D40: 0.05 | E40: 0.04 | F40: 0.04 | H40: Documento 5.3.3: menor o igual a 7 % en E2 y a 5 % en E3
B41: Equipos promedio por cliente — Plan Inicial | C41: 18 | D41: 20 | E41: 22 | F41: 24 | H41: Segmento A: de 10 a 80 equipos (documento, 4.2). Por encima de los 15 que incluye el plan, así que genera facturación por equipo adicional
B42: Equipos promedio por cliente — Plan Estándar | C42: 90 | D42: 100 | E42: 110 | F42: 120 | H42: Segmento B: de 80 a 250 equipos
B43: Equipos promedio por cliente — Plan Partner | C43: 15 | D43: 16 | E43: 17 | F43: 18 | H43: Clientes chicos gestionados por el canal
B45: Las filas marcadas PENDIENTE no tienen valor cargado a propósito: son las que exigen fuente citada y no se completan a ojo.

Sheet Planes
A1: « Inicio
B2: LÍNEAS DE SERVICIO
B3: Precios de la sección 5.3.6 del documento. Costos variables unitarios de la sección 6.5.3.
B6: Plan | C6: Segmento | D6: Abono mensual | E6: Equipos incluidos | F6: Equipo adicional | G6: CV infraestructura | H6: CV soporte | I6: CV servicio de IA | J6: CV total | K6: Margen de contribución
B7: Plan Inicial | C7: A | D7: 89000 | E7: 15 | F7: 4200 | G7: 3000 | H7: 4000 | I7: 1500 | J7: =SUM(G7:I7) | K7: =(D7-J7)/D7 | L7: Precio revisado (D-14). USD 46,8 por 15 equipos: USD 3,1 por equipo
B8: Plan Estándar | C8: B | D8: 239000 | E8: 50 | F8: 3500 | G8: 9000 | H8: 12000 | I8: 4000 | J8: =SUM(G8:I8) | K8: =(D8-J8)/D8 | L8: Precio revisado (D-14). USD 125,8 por 50 equipos: USD 2,5 por equipo
B9: Plan Partner | C9: C | D9: 69000 | E9: 30 | F9: 2800 | G9: 2500 | H9: 2500 | I9: 2000 | J9: =SUM(G9:I9) | K9: =(D9-J9)/D9 | L9: Precio revisado (D-14). Mas bajo por equipo: el partner aporta el canal y la primera linea de soporte
B11: El margen de contribución de las tres líneas queda entre el 74 % y el 76 %, que es lo que sostiene la sección 6.5.3. Si al cambiar un supuesto alguno se aparta de ese rango, hay que corregir el documento o el supuesto: no pueden decir cosas distintas.

Sheet Proyección de ventas
A1: « Inicio
B2: PROYECCIÓN DE VENTAS
B3: Clientes por línea de servicio, mes a mes. Las altas salen del embudo comercial, de la conversión de pilotos y del canal de partners; las tres fuentes se modelan por separado.
C7: 2027 | P7: 2028 | AC7: 2029 | AP7: 2030
C8: Ene | D8: Feb | E8: Mar | F8: Abr | G8: May | H8: Jun | I8: Jul | J8: Ago | K8: Sep | L8: Oct | M8: Nov | N8: Dic | O8: Total 2027 | P8: Ene | Q8: Feb | R8: Mar | S8: Abr | T8: May | U8: Jun | V8: Jul | W8: Ago | X8: Sep | Y8: Oct | Z8: Nov | AA8: Dic | AB8: Total 2028 | AC8: Ene | AD8: Feb | AE8: Mar | AF8: Abr | AG8: May | AH8: Jun | AI8: Jul | AJ8: Ago | AK8: Sep | AL8: Oct | AM8: Nov | AN8: Dic | AO8: Total 2029 | AP8: Ene | AQ8: Feb | AR8: Mar | AS8: Abr | AT8: May | AU8: Jun | AV8: Jul | AW8: Ago | AX8: Sep | AY8: Oct | AZ8: Nov | BA8: Dic | BB8: Total 2030
B10: Embudo comercial
A11: EMBUDO | B11: Visitas web | C11: =Hipótesis!$C$24 | D11: =C11*(1+Hipótesis!$C$25) | E11: =D11*(1+Hipótesis!$C$25) | F11: =E11*(1+Hipótesis!$C$25) | G11: =F11*(1+Hipótesis!$C$25) | H11: =G11*(1+Hipótesis!$C$25) | I11: =H11*(1+Hipótesis!$C$25) | J11: =I11*(1+Hipótesis!$C$25) | K11: =J11*(1+Hipótesis!$C$25) | ... N11: =M11*(1+Hipótesis!$C$25) | O11: =SUM(C11:N11) | P11: =N11*(1+Hipótesis!$D$25) | Q11: =P11*(1+Hipótesis!$D$25) | R11: =Q11*(1+Hipótesis!$D$25) | S11: =R11*(1+Hipótesis!$D$25) | T11: =S11*(1+Hipótesis!$D$25) | U11: =T11*(1+Hipótesis!$D$25) | V11: =U11*(1+Hipótesis!$D$25) | W11: =V11*(1+Hipótesis!$D$25) | X11: =W11*(1+Hipótesis!$D$25) | ... AA11: =Z11*(1+Hipótesis!$D$25) | AB11: =SUM(P11:AA11) | AC11: =AA11*(1+Hipótesis!$E$25) | AD11: =AC11*(1+Hipótesis!$E$25) | AE11: =AD11*(1+Hipótesis!$E$25) | AF11: =AE11*(1+Hipótesis!$E$25) | AG11: =AF11*(1+Hipótesis!$E$25) | AH11: =AG11*(1+Hipótesis!$E$25) | AI11: =AH11*(1+Hipótesis!$E$25) | AJ11: =AI11*(1+Hipótesis!$E$25) | AK11: =AJ11*(1+Hipótesis!$E$25) | ... AN11: =AM11*(1+Hipótesis!$E$25) | AO11: =SUM(AC11:AN11) | AP11: =AN11*(1+Hipótesis!$F$25) | AQ11: =AP11*(1+Hipótesis!$F$25) | AR11: =AQ11*(1+Hipótesis!$F$25) | AS11: =AR11*(1+Hipótesis!$F$25) | AT11: =AS11*(1+Hipótesis!$F$25) | AU11: =AT11*(1+Hipótesis!$F$25) | AV11: =AU11*(1+Hipótesis!$F$25) | AW11: =AV11*(1+Hipótesis!$F$25) | AX11: =AW11*(1+Hipótesis!$F$25) | ... BA11: =AZ11*(1+Hipótesis!$F$25) | BB11: =SUM(AP11:BA11)
B12: Leads | C12: =C11*Hipótesis!$C$26 | D12: =D11*Hipótesis!$C$26 | E12: =E11*Hipótesis!$C$26 | F12: =F11*Hipótesis!$C$26 | G12: =G11*Hipótesis!$C$26 | H12: =H11*Hipótesis!$C$26 | I12: =I11*Hipótesis!$C$26 | J12: =J11*Hipótesis!$C$26 | ... N12: =N11*Hipótesis!$C$26 | O12: =SUM(C12:N12) | P12: =P11*Hipótesis!$C$26 | Q12: =Q11*Hipótesis!$C$26 | R12: =R11*Hipótesis!$C$26 | S12: =S11*Hipótesis!$C$26 | T12: =T11*Hipótesis!$C$26 | U12: =U11*Hipótesis!$C$26 | V12: =V11*Hipótesis!$C$26 | W12: =W11*Hipótesis!$C$26 | ... AA12: =AA11*Hipótesis!$C$26 | AB12: =SUM(P12:AA12) | AC12: =AC11*Hipótesis!$C$26 | AD12: =AD11*Hipótesis!$C$26 | AE12: =AE11*Hipótesis!$C$26 | AF12: =AF11*Hipótesis!$C$26 | AG12: =AG11*Hipótesis!$C$26 | AH12: =AH11*Hipótesis!$C$26 | AI12: =AI11*Hipótesis!$C$26 | AJ12: =AJ11*Hipótesis!$C$26 | ... AN12: =AN11*Hipótesis!$C$26 | AO12: =SUM(AC12:AN12) | AP12: =AP11*Hipótesis!$C$26 | AQ12: =AQ11*Hipótesis!$C$26 | AR12: =AR11*Hipótesis!$C$26 | AS12: =AS11*Hipótesis!$C$26 | AT12: =AT11*Hipótesis!$C$26 | AU12: =AU11*Hipótesis!$C$26 | AV12: =AV11*Hipótesis!$C$26 | AW12: =AW11*Hipótesis!$C$26 | ... BA12: =BA11*Hipótesis!$C$26 | BB12: =SUM(AP12:BA12)
B13: Demos calificadas | C13: =C12*Hipótesis!$C$27 | D13: =D12*Hipótesis!$C$27 | E13: =E12*Hipótesis!$C$27 | F13: =F12*Hipótesis!$C$27 | G13: =G12*Hipótesis!$C$27 | H13: =H12*Hipótesis!$C$27 | I13: =I12*Hipótesis!$C$27 | J13: =J12*Hipótesis!$C$27 | ... N13: =N12*Hipótesis!$C$27 | O13: =SUM(C13:N13) | P13: =P12*Hipótesis!$C$27 | Q13: =Q12*Hipótesis!$C$27 | R13: =R12*Hipótesis!$C$27 | S13: =S12*Hipótesis!$C$27 | T13: =T12*Hipótesis!$C$27 | U13: =U12*Hipótesis!$C$27 | V13: =V12*Hipótesis!$C$27 | W13: =W12*Hipótesis!$C$27 | ... AA13: =AA12*Hipótesis!$C$27 | AB13: =SUM(P13:AA13) | AC13: =AC12*Hipótesis!$C$27 | AD13: =AD12*Hipótesis!$C$27 | AE13: =AE12*Hipótesis!$C$27 | AF13: =AF12*Hipótesis!$C$27 | AG13: =AG12*Hipótesis!$C$27 | AH13: =AH12*Hipótesis!$C$27 | AI13: =AI12*Hipótesis!$C$27 | AJ13: =AJ12*Hipótesis!$C$27 | ... AN13: =AN12*Hipótesis!$C$27 | AO13: =SUM(AC13:AN13) | AP13: =AP12*Hipótesis!$C$27 | AQ13: =AQ12*Hipótesis!$C$27 | AR13: =AR12*Hipótesis!$C$27 | AS13: =AS12*Hipótesis!$C$27 | AT13: =AT12*Hipótesis!$C$27 | AU13: =AU12*Hipótesis!$C$27 | AV13: =AV12*Hipótesis!$C$27 | AW13: =AW12*Hipótesis!$C$27 | ... BA13: =BA12*Hipótesis!$C$27 | BB13: =SUM(AP13:BA13)
B14: Pruebas gratuitas iniciadas | C14: =C13*Hipótesis!$C$28 | D14: =D13*Hipótesis!$C$28 | E14: =E13*Hipótesis!$C$28 | F14: =F13*Hipótesis!$C$28 | G14: =G13*Hipótesis!$C$28 | H14: =H13*Hipótesis!$C$28 | I14: =I13*Hipótesis!$C$28 | J14: =J13*Hipótesis!$C$28 | ... N14: =N13*Hipótesis!$C$28 | O14: =SUM(C14:N14) | P14: =P13*Hipótesis!$C$28 | Q14: =Q13*Hipótesis!$C$28 | R14: =R13*Hipótesis!$C$28 | S14: =S13*Hipótesis!$C$28 | T14: =T13*Hipótesis!$C$28 | U14: =U13*Hipótesis!$C$28 | V14: =V13*Hipótesis!$C$28 | W14: =W13*Hipótesis!$C$28 | ... AA14: =AA13*Hipótesis!$C$28 | AB14: =SUM(P14:AA14) | AC14: =AC13*Hipótesis!$C$28 | AD14: =AD13*Hipótesis!$C$28 | AE14: =AE13*Hipótesis!$C$28 | AF14: =AF13*Hipótesis!$C$28 | AG14: =AG13*Hipótesis!$C$28 | AH14: =AH13*Hipótesis!$C$28 | AI14: =AI13*Hipótesis!$C$28 | AJ14: =AJ13*Hipótesis!$C$28 | ... AN14: =AN13*Hipótesis!$C$28 | AO14: =SUM(AC14:AN14) | AP14: =AP13*Hipótesis!$C$28 | AQ14: =AQ13*Hipótesis!$C$28 | AR14: =AR13*Hipótesis!$C$28 | AS14: =AS13*Hipótesis!$C$28 | AT14: =AT13*Hipótesis!$C$28 | AU14: =AU13*Hipótesis!$C$28 | AV14: =AV13*Hipótesis!$C$28 | AW14: =AW13*Hipótesis!$C$28 | ... BA14: =BA13*Hipótesis!$C$28 | BB14: =SUM(AP14:BA14)
B15: Clientes nuevos por embudo directo | C15: =IF(1<Hipótesis!$C$35,0,C14*Hipótesis!$C$29) | D15: =IF(2<Hipótesis!$C$35,0,D14*Hipótesis!$C$29) | E15: =IF(3<Hipótesis!$C$35,0,E14*Hipótesis!$C$29) | F15: =IF(4<Hipótesis!$C$35,0,F14*Hipótesis!$C$29) | G15: =IF(5<Hipótesis!$C$35,0,G14*Hipótesis!$C$29) | H15: =IF(6<Hipótesis!$C$35,0,H14*Hipótesis!$C$29) | I15: =IF(7<Hipótesis!$C$35,0,I14*Hipótesis!$C$29) | J15: =IF(8<Hipótesis!$C$35,0,J14*Hipótesis!$C$29) | K15: =IF(9<Hipótesis!$C$35,0,K14*Hipótesis!$C$29) | L15: =IF(10<Hipótesis!$C$35,0,L14*Hipótesis!$C$29) | M15: =IF(11<Hipótesis!$C$35,0,M14*Hipótesis!$C$29) | N15: =IF(12<Hipótesis!$C$35,0,N14*Hipótesis!$C$29) | O15: =SUM(C15:N15) | P15: =IF(13<Hipótesis!$C$35,0,P14*Hipótesis!$C$29) | Q15: =IF(14<Hipótesis!$C$35,0,Q14*Hipótesis!$C$29) | R15: =IF(15<Hipótesis!$C$35,0,R14*Hipótesis!$C$29) | S15: =IF(16<Hipótesis!$C$35,0,S14*Hipótesis!$C$29) | T15: =IF(17<Hipótesis!$C$35,0,T14*Hipótesis!$C$29) | U15: =IF(18<Hipótesis!$C$35,0,U14*Hipótesis!$C$29) | V15: =IF(19<Hipótesis!$C$35,0,V14*Hipótesis!$C$29) | W15: =IF(20<Hipótesis!$C$35,0,W14*Hipótesis!$C$29) | X15: =IF(21<Hipótesis!$C$35,0,X14*Hipótesis!$C$29) | Y15: =IF(22<Hipótesis!$C$35,0,Y14*Hipótesis!$C$29) | Z15: =IF(23<Hipótesis!$C$35,0,Z14*Hipótesis!$C$29) | AA15: =IF(24<Hipótesis!$C$35,0,AA14*Hipótesis!$C$29) | AB15: =SUM(P15:AA15) | AC15: =IF(25<Hipótesis!$C$35,0,AC14*Hipótesis!$C$29) | AD15: =IF(26<Hipótesis!$C$35,0,AD14*Hipótesis!$C$29) | AE15: =IF(27<Hipótesis!$C$35,0,AE14*Hipótesis!$C$29) | AF15: =IF(28<Hipótesis!$C$35,0,AF14*Hipótesis!$C$29) | AG15: =IF(29<Hipótesis!$C$35,0,AG14*Hipótesis!$C$29) | AH15: =IF(30<Hipótesis!$C$35,0,AH14*Hipótesis!$C$29) | AI15: =IF(31<Hipótesis!$C$35,0,AI14*Hipótesis!$C$29) | AJ15: =IF(32<Hipótesis!$C$35,0,AJ14*Hipótesis!$C$29) | AK15: =IF(33<Hipótesis!$C$35,0,AK14*Hipótesis!$C$29) | AL15: =IF(34<Hipótesis!$C$35,0,AL14*Hipótesis!$C$29) | AM15: =IF(35<Hipótesis!$C$35,0,AM14*Hipótesis!$C$29) | AN15: =IF(36<Hipótesis!$C$35,0,AN14*Hipótesis!$C$29) | AO15: =SUM(AC15:AN15) | AP15: =IF(37<Hipótesis!$C$35,0,AP14*Hipótesis!$C$29) | AQ15: =IF(38<Hipótesis!$C$35,0,AQ14*Hipótesis!$C$29) | AR15: =IF(39<Hipótesis!$C$35,0,AR14*Hipótesis!$C$29) | AS15: =IF(40<Hipótesis!$C$35,0,AS14*Hipótesis!$C$29) | AT15: =IF(41<Hipótesis!$C$35,0,AT14*Hipótesis!$C$29) | AU15: =IF(42<Hipótesis!$C$35,0,AU14*Hipótesis!$C$29) | AV15: =IF(43<Hipótesis!$C$35,0,AV14*Hipótesis!$C$29) | AW15: =IF(44<Hipótesis!$C$35,0,AW14*Hipótesis!$C$29) | AX15: =IF(45<Hipótesis!$C$35,0,AX14*Hipótesis!$C$29) | AY15: =IF(46<Hipótesis!$C$35,0,AY14*Hipótesis!$C$29) | AZ15: =IF(47<Hipótesis!$C$35,0,AZ14*Hipótesis!$C$29) | BA15: =IF(48<Hipótesis!$C$35,0,BA14*Hipótesis!$C$29) | BB15: =SUM(AP15:BA15)
B17: Plan Inicial — Segmento A
A18: PLAN INICIAL | B18: Base al inicio del mes | C18: 0 | D18: =C22 | E18: =D22 | F18: =E22 | G18: =F22 | H18: =G22 | I18: =H22 | J18: =I22 | K18: =J22 | ... N18: =M22 | P18: =N22 | Q18: =P22 | R18: =Q22 | S18: =R22 | T18: =S22 | U18: =T22 | V18: =U22 | W18: =V22 | X18: =W22 | ... AA18: =Z22 | AC18: =AA22 | AD18: =AC22 | AE18: =AD22 | AF18: =AE22 | AG18: =AF22 | AH18: =AG22 | AI18: =AH22 | AJ18: =AI22 | AK18: =AJ22 | ... AN18: =AM22 | AP18: =AN22 | AQ18: =AP22 | AR18: =AQ22 | AS18: =AR22 | AT18: =AS22 | AU18: =AT22 | AV18: =AU22 | AW18: =AV22 | AX18: =AW22 | ... BA18: =AZ22
B19: Altas por embudo directo | C19: =C15 | D19: =D15 | E19: =E15 | F19: =F15 | G19: =G15 | H19: =H15 | I19: =I15 | J19: =J15 | ... N19: =N15 | O19: =SUM(C19:N19) | P19: =P15 | Q19: =Q15 | R19: =R15 | S19: =S15 | T19: =T15 | U19: =U15 | V19: =V15 | W19: =W15 | ... AA19: =AA15 | AB19: =SUM(P19:AA19) | AC19: =AC15 | AD19: =AD15 | AE19: =AE15 | AF19: =AF15 | AG19: =AG15 | AH19: =AH15 | AI19: =AI15 | AJ19: =AJ15 | ... AN19: =AN15 | AO19: =SUM(AC19:AN19) | AP19: =AP15 | AQ19: =AQ15 | AR19: =AR15 | AS19: =AS15 | AT19: =AT15 | AU19: =AU15 | AV19: =AV15 | AW19: =AW15 | ... BA19: =BA15 | BB19: =SUM(AP19:BA19)
B20: Altas por conversión de pilotos | C20: =IF(AND(1=Hipótesis!$C$35,1=1),Hipótesis!$C$33*Hipótesis!$C$34,0) | D20: =IF(AND(2=Hipótesis!$C$35,1=1),Hipótesis!$C$33*Hipótesis!$C$34,0) | E20: =IF(AND(3=Hipótesis!$C$35,1=1),Hipótesis!$C$33*Hipótesis!$C$34,0) | F20: =IF(AND(4=Hipótesis!$C$35,1=1),Hipótesis!$C$33*Hipótesis!$C$34,0) | G20: =IF(AND(5=Hipótesis!$C$35,1=1),Hipótesis!$C$33*Hipótesis!$C$34,0) | H20: =IF(AND(6=Hipótesis!$C$35,1=1),Hipótesis!$C$33*Hipótesis!$C$34,0) | I20: =IF(AND(7=Hipótesis!$C$35,1=1),Hipótesis!$C$33*Hipótesis!$C$34,0) | J20: =IF(AND(8=Hipótesis!$C$35,1=1),Hipótesis!$C$33*Hipótesis!$C$34,0) | K20: =IF(AND(9=Hipótesis!$C$35,1=1),Hipótesis!$C$33*Hipótesis!$C$34,0) | L20: =IF(AND(10=Hipótesis!$C$35,1=1),Hipótesis!$C$33*Hipótesis!$C$34,0) | M20: =IF(AND(11=Hipótesis!$C$35,1=1),Hipótesis!$C$33*Hipótesis!$C$34,0) | N20: =IF(AND(12=Hipótesis!$C$35,1=1),Hipótesis!$C$33*Hipótesis!$C$34,0) | O20: =SUM(C20:N20) | P20: =IF(AND(13=Hipótesis!$C$35,2=1),Hipótesis!$C$33*Hipótesis!$C$34,0) | Q20: =IF(AND(14=Hipótesis!$C$35,2=1),Hipótesis!$C$33*Hipótesis!$C$34,0) | R20: =IF(AND(15=Hipótesis!$C$35,2=1),Hipótesis!$C$33*Hipótesis!$C$34,0) | S20: =IF(AND(16=Hipótesis!$C$35,2=1),Hipótesis!$C$33*Hipótesis!$C$34,0) | T20: =IF(AND(17=Hipótesis!$C$35,2=1),Hipótesis!$C$33*Hipótesis!$C$34,0) | U20: =IF(AND(18=Hipótesis!$C$35,2=1),Hipótesis!$C$33*Hipótesis!$C$34,0) | V20: =IF(AND(19=Hipótesis!$C$35,2=1),Hipótesis!$C$33*Hipótesis!$C$34,0) | W20: =IF(AND(20=Hipótesis!$C$35,2=1),Hipótesis!$C$33*Hipótesis!$C$34,0) | X20: =IF(AND(21=Hipótesis!$C$35,2=1),Hipótesis!$C$33*Hipótesis!$C$34,0) | Y20: =IF(AND(22=Hipótesis!$C$35,2=1),Hipótesis!$C$33*Hipótesis!$C$34,0) | Z20: =IF(AND(23=Hipótesis!$C$35,2=1),Hipótesis!$C$33*Hipótesis!$C$34,0) | AA20: =IF(AND(24=Hipótesis!$C$35,2=1),Hipótesis!$C$33*Hipótesis!$C$34,0) | AB20: =SUM(P20:AA20) | AC20: =IF(AND(25=Hipótesis!$C$35,3=1),Hipótesis!$C$33*Hipótesis!$C$34,0) | AD20: =IF(AND(26=Hipótesis!$C$35,3=1),Hipótesis!$C$33*Hipótesis!$C$34,0) | AE20: =IF(AND(27=Hipótesis!$C$35,3=1),Hipótesis!$C$33*Hipótesis!$C$34,0) | AF20: =IF(AND(28=Hipótesis!$C$35,3=1),Hipótesis!$C$33*Hipótesis!$C$34,0) | AG20: =IF(AND(29=Hipótesis!$C$35,3=1),Hipótesis!$C$33*Hipótesis!$C$34,0) | AH20: =IF(AND(30=Hipótesis!$C$35,3=1),Hipótesis!$C$33*Hipótesis!$C$34,0) | AI20: =IF(AND(31=Hipótesis!$C$35,3=1),Hipótesis!$C$33*Hipótesis!$C$34,0) | AJ20: =IF(AND(32=Hipótesis!$C$35,3=1),Hipótesis!$C$33*Hipótesis!$C$34,0) | AK20: =IF(AND(33=Hipótesis!$C$35,3=1),Hipótesis!$C$33*Hipótesis!$C$34,0) | AL20: =IF(AND(34=Hipótesis!$C$35,3=1),Hipótesis!$C$33*Hipótesis!$C$34,0) | AM20: =IF(AND(35=Hipótesis!$C$35,3=1),Hipótesis!$C$33*Hipótesis!$C$34,0) | AN20: =IF(AND(36=Hipótesis!$C$35,3=1),Hipótesis!$C$33*Hipótesis!$C$34,0) | AO20: =SUM(AC20:AN20) | AP20: =IF(AND(37=Hipótesis!$C$35,4=1),Hipótesis!$C$33*Hipótesis!$C$34,0) | AQ20: =IF(AND(38=Hipótesis!$C$35,4=1),Hipótesis!$C$33*Hipótesis!$C$34,0) | AR20: =IF(AND(39=Hipótesis!$C$35,4=1),Hipótesis!$C$33*Hipótesis!$C$34,0) | AS20: =IF(AND(40=Hipótesis!$C$35,4=1),Hipótesis!$C$33*Hipótesis!$C$34,0) | AT20: =IF(AND(41=Hipótesis!$C$35,4=1),Hipótesis!$C$33*Hipótesis!$C$34,0) | AU20: =IF(AND(42=Hipótesis!$C$35,4=1),Hipótesis!$C$33*Hipótesis!$C$34,0) | AV20: =IF(AND(43=Hipótesis!$C$35,4=1),Hipótesis!$C$33*Hipótesis!$C$34,0) | AW20: =IF(AND(44=Hipótesis!$C$35,4=1),Hipótesis!$C$33*Hipótesis!$C$34,0) | AX20: =IF(AND(45=Hipótesis!$C$35,4=1),Hipótesis!$C$33*Hipótesis!$C$34,0) | AY20: =IF(AND(46=Hipótesis!$C$35,4=1),Hipótesis!$C$33*Hipótesis!$C$34,0) | AZ20: =IF(AND(47=Hipótesis!$C$35,4=1),Hipótesis!$C$33*Hipótesis!$C$34,0) | BA20: =IF(AND(48=Hipótesis!$C$35,4=1),Hipótesis!$C$33*Hipótesis!$C$34,0) | BB20: =SUM(AP20:BA20)
B21: Bajas | C21: =-C18*Hipótesis!$C$40 | D21: =-D18*Hipótesis!$C$40 | E21: =-E18*Hipótesis!$C$40 | F21: =-F18*Hipótesis!$C$40 | G21: =-G18*Hipótesis!$C$40 | H21: =-H18*Hipótesis!$C$40 | I21: =-I18*Hipótesis!$C$40 | J21: =-J18*Hipótesis!$C$40 | ... N21: =-N18*Hipótesis!$C$40 | O21: =SUM(C21:N21) | P21: =-P18*Hipótesis!$D$40 | Q21: =-Q18*Hipótesis!$D$40 | R21: =-R18*Hipótesis!$D$40 | S21: =-S18*Hipótesis!$D$40 | T21: =-T18*Hipótesis!$D$40 | U21: =-U18*Hipótesis!$D$40 | V21: =-V18*Hipótesis!$D$40 | W21: =-W18*Hipótesis!$D$40 | ... AA21: =-AA18*Hipótesis!$D$40 | AB21: =SUM(P21:AA21) | AC21: =-AC18*Hipótesis!$E$40 | AD21: =-AD18*Hipótesis!$E$40 | AE21: =-AE18*Hipótesis!$E$40 | AF21: =-AF18*Hipótesis!$E$40 | AG21: =-AG18*Hipótesis!$E$40 | AH21: =-AH18*Hipótesis!$E$40 | AI21: =-AI18*Hipótesis!$E$40 | AJ21: =-AJ18*Hipótesis!$E$40 | ... AN21: =-AN18*Hipótesis!$E$40 | AO21: =SUM(AC21:AN21) | AP21: =-AP18*Hipótesis!$F$40 | AQ21: =-AQ18*Hipótesis!$F$40 | AR21: =-AR18*Hipótesis!$F$40 | AS21: =-AS18*Hipótesis!$F$40 | AT21: =-AT18*Hipótesis!$F$40 | AU21: =-AU18*Hipótesis!$F$40 | AV21: =-AV18*Hipótesis!$F$40 | AW21: =-AW18*Hipótesis!$F$40 | ... BA21: =-BA18*Hipótesis!$F$40 | BB21: =SUM(AP21:BA21)
B22: Base activa al cierre | C22: =SUM(C18:C21) | D22: =SUM(D18:D21) | E22: =SUM(E18:E21) | F22: =SUM(F18:F21) | G22: =SUM(G18:G21) | H22: =SUM(H18:H21) | I22: =SUM(I18:I21) | J22: =SUM(J18:J21) | ... N22: =SUM(N18:N21) | O22: =N22 | P22: =SUM(P18:P21) | Q22: =SUM(Q18:Q21) | R22: =SUM(R18:R21) | S22: =SUM(S18:S21) | T22: =SUM(T18:T21) | U22: =SUM(U18:U21) | V22: =SUM(V18:V21) | W22: =SUM(W18:W21) | ... AA22: =SUM(AA18:AA21) | AB22: =AA22 | AC22: =SUM(AC18:AC21) | AD22: =SUM(AD18:AD21) | AE22: =SUM(AE18:AE21) | AF22: =SUM(AF18:AF21) | AG22: =SUM(AG18:AG21) | AH22: =SUM(AH18:AH21) | AI22: =SUM(AI18:AI21) | AJ22: =SUM(AJ18:AJ21) | ... AN22: =SUM(AN18:AN21) | AO22: =AN22 | AP22: =SUM(AP18:AP21) | AQ22: =SUM(AQ18:AQ21) | AR22: =SUM(AR18:AR21) | AS22: =SUM(AS18:AS21) | AT22: =SUM(AT18:AT21) | AU22: =SUM(AU18:AU21) | AV22: =SUM(AV18:AV21) | AW22: =SUM(AW18:AW21) | ... BA22: =SUM(BA18:BA21) | BB22: =BA22
B24: Plan Estándar — Segmento B | H24: Las altas del Segmento B son un supuesto directo: ciclo de venta de 60 a 90 días (5.3.5) y el primer cliente en la Etapa E3.
B25: Altas por año (supuesto) | C25: 1.2 | D25: 4.8 | E25: 9.6 | F25: 14.4 | H25: Total de clientes nuevos del Plan Estándar en cada año
A26: PLAN ESTÁNDAR | B26: Base al inicio del mes | C26: 0 | D26: =C29 | E26: =D29 | F26: =E29 | G26: =F29 | H26: =G29 | I26: =H29 | J26: =I29 | K26: =J29 | ... N26: =M29 | P26: =N29 | Q26: =P29 | R26: =Q29 | S26: =R29 | T26: =S29 | U26: =T29 | V26: =U29 | W26: =V29 | X26: =W29 | ... AA26: =Z29 | AC26: =AA29 | AD26: =AC29 | AE26: =AD29 | AF26: =AE29 | AG26: =AF29 | AH26: =AG29 | AI26: =AH29 | AJ26: =AI29 | AK26: =AJ29 | ... AN26: =AM29 | AP26: =AN29 | AQ26: =AP29 | AR26: =AQ29 | AS26: =AR29 | AT26: =AS29 | AU26: =AT29 | AV26: =AU29 | AW26: =AV29 | AX26: =AW29 | ... BA26: =AZ29
B27: Altas | C27: =IF(1<9,0,Hipótesis!$C$25/IF(1=1,4,12)) | D27: =IF(2<9,0,Hipótesis!$C$25/IF(1=1,4,12)) | E27: =IF(3<9,0,Hipótesis!$C$25/IF(1=1,4,12)) | F27: =IF(4<9,0,Hipótesis!$C$25/IF(1=1,4,12)) | G27: =IF(5<9,0,Hipótesis!$C$25/IF(1=1,4,12)) | H27: =IF(6<9,0,Hipótesis!$C$25/IF(1=1,4,12)) | I27: =IF(7<9,0,Hipótesis!$C$25/IF(1=1,4,12)) | J27: =IF(8<9,0,Hipótesis!$C$25/IF(1=1,4,12)) | K27: =IF(9<9,0,Hipótesis!$C$25/IF(1=1,4,12)) | L27: =IF(10<9,0,Hipótesis!$C$25/IF(1=1,4,12)) | M27: =IF(11<9,0,Hipótesis!$C$25/IF(1=1,4,12)) | N27: =IF(12<9,0,Hipótesis!$C$25/IF(1=1,4,12)) | O27: =SUM(C27:N27) | P27: =IF(13<9,0,Hipótesis!$D$25/IF(2=1,4,12)) | Q27: =IF(14<9,0,Hipótesis!$D$25/IF(2=1,4,12)) | R27: =IF(15<9,0,Hipótesis!$D$25/IF(2=1,4,12)) | S27: =IF(16<9,0,Hipótesis!$D$25/IF(2=1,4,12)) | T27: =IF(17<9,0,Hipótesis!$D$25/IF(2=1,4,12)) | U27: =IF(18<9,0,Hipótesis!$D$25/IF(2=1,4,12)) | V27: =IF(19<9,0,Hipótesis!$D$25/IF(2=1,4,12)) | W27: =IF(20<9,0,Hipótesis!$D$25/IF(2=1,4,12)) | X27: =IF(21<9,0,Hipótesis!$D$25/IF(2=1,4,12)) | Y27: =IF(22<9,0,Hipótesis!$D$25/IF(2=1,4,12)) | Z27: =IF(23<9,0,Hipótesis!$D$25/IF(2=1,4,12)) | AA27: =IF(24<9,0,Hipótesis!$D$25/IF(2=1,4,12)) | AB27: =SUM(P27:AA27) | AC27: =IF(25<9,0,Hipótesis!$E$25/IF(3=1,4,12)) | AD27: =IF(26<9,0,Hipótesis!$E$25/IF(3=1,4,12)) | AE27: =IF(27<9,0,Hipótesis!$E$25/IF(3=1,4,12)) | AF27: =IF(28<9,0,Hipótesis!$E$25/IF(3=1,4,12)) | AG27: =IF(29<9,0,Hipótesis!$E$25/IF(3=1,4,12)) | AH27: =IF(30<9,0,Hipótesis!$E$25/IF(3=1,4,12)) | AI27: =IF(31<9,0,Hipótesis!$E$25/IF(3=1,4,12)) | AJ27: =IF(32<9,0,Hipótesis!$E$25/IF(3=1,4,12)) | AK27: =IF(33<9,0,Hipótesis!$E$25/IF(3=1,4,12)) | AL27: =IF(34<9,0,Hipótesis!$E$25/IF(3=1,4,12)) | AM27: =IF(35<9,0,Hipótesis!$E$25/IF(3=1,4,12)) | AN27: =IF(36<9,0,Hipótesis!$E$25/IF(3=1,4,12)) | AO27: =SUM(AC27:AN27) | AP27: =IF(37<9,0,Hipótesis!$F$25/IF(4=1,4,12)) | AQ27: =IF(38<9,0,Hipótesis!$F$25/IF(4=1,4,12)) | AR27: =IF(39<9,0,Hipótesis!$F$25/IF(4=1,4,12)) | AS27: =IF(40<9,0,Hipótesis!$F$25/IF(4=1,4,12)) | AT27: =IF(41<9,0,Hipótesis!$F$25/IF(4=1,4,12)) | AU27: =IF(42<9,0,Hipótesis!$F$25/IF(4=1,4,12)) | AV27: =IF(43<9,0,Hipótesis!$F$25/IF(4=1,4,12)) | AW27: =IF(44<9,0,Hipótesis!$F$25/IF(4=1,4,12)) | AX27: =IF(45<9,0,Hipótesis!$F$25/IF(4=1,4,12)) | AY27: =IF(46<9,0,Hipótesis!$F$25/IF(4=1,4,12)) | AZ27: =IF(47<9,0,Hipótesis!$F$25/IF(4=1,4,12)) | BA27: =IF(48<9,0,Hipótesis!$F$25/IF(4=1,4,12)) | BB27: =SUM(AP27:BA27)
B28: Bajas | C28: =-C26*Hipótesis!$C$40 | D28: =-D26*Hipótesis!$C$40 | E28: =-E26*Hipótesis!$C$40 | F28: =-F26*Hipótesis!$C$40 | G28: =-G26*Hipótesis!$C$40 | H28: =-H26*Hipótesis!$C$40 | I28: =-I26*Hipótesis!$C$40 | J28: =-J26*Hipótesis!$C$40 | ... N28: =-N26*Hipótesis!$C$40 | O28: =SUM(C28:N28) | P28: =-P26*Hipótesis!$D$40 | Q28: =-Q26*Hipótesis!$D$40 | R28: =-R26*Hipótesis!$D$40 | S28: =-S26*Hipótesis!$D$40 | T28: =-T26*Hipótesis!$D$40 | U28: =-U26*Hipótesis!$D$40 | V28: =-V26*Hipótesis!$D$40 | W28: =-W26*Hipótesis!$D$40 | ... AA28: =-AA26*Hipótesis!$D$40 | AB28: =SUM(P28:AA28) | AC28: =-AC26*Hipótesis!$E$40 | AD28: =-AD26*Hipótesis!$E$40 | AE28: =-AE26*Hipótesis!$E$40 | AF28: =-AF26*Hipótesis!$E$40 | AG28: =-AG26*Hipótesis!$E$40 | AH28: =-AH26*Hipótesis!$E$40 | AI28: =-AI26*Hipótesis!$E$40 | AJ28: =-AJ26*Hipótesis!$E$40 | ... AN28: =-AN26*Hipótesis!$E$40 | AO28: =SUM(AC28:AN28) | AP28: =-AP26*Hipótesis!$F$40 | AQ28: =-AQ26*Hipótesis!$F$40 | AR28: =-AR26*Hipótesis!$F$40 | AS28: =-AS26*Hipótesis!$F$40 | AT28: =-AT26*Hipótesis!$F$40 | AU28: =-AU26*Hipótesis!$F$40 | AV28: =-AV26*Hipótesis!$F$40 | AW28: =-AW26*Hipótesis!$F$40 | ... BA28: =-BA26*Hipótesis!$F$40 | BB28: =SUM(AP28:BA28)
B29: Base activa al cierre | C29: =SUM(C26:C28) | D29: =SUM(D26:D28) | E29: =SUM(E26:E28) | F29: =SUM(F26:F28) | G29: =SUM(G26:G28) | H29: =SUM(H26:H28) | I29: =SUM(I26:I28) | J29: =SUM(J26:J28) | ... N29: =SUM(N26:N28) | O29: =N29 | P29: =SUM(P26:P28) | Q29: =SUM(Q26:Q28) | R29: =SUM(R26:R28) | S29: =SUM(S26:S28) | T29: =SUM(T26:T28) | U29: =SUM(U26:U28) | V29: =SUM(V26:V28) | W29: =SUM(W26:W28) | ... AA29: =SUM(AA26:AA28) | AB29: =AA29 | AC29: =SUM(AC26:AC28) | AD29: =SUM(AD26:AD28) | AE29: =SUM(AE26:AE28) | AF29: =SUM(AF26:AF28) | AG29: =SUM(AG26:AG28) | AH29: =SUM(AH26:AH28) | AI29: =SUM(AI26:AI28) | AJ29: =SUM(AJ26:AJ28) | ... AN29: =SUM(AN26:AN28) | AO29: =AN29 | AP29: =SUM(AP26:AP28) | AQ29: =SUM(AQ26:AQ28) | AR29: =SUM(AR26:AR28) | AS29: =SUM(AS26:AS28) | AT29: =SUM(AT26:AT28) | AU29: =SUM(AU26:AU28) | AV29: =SUM(AV26:AV28) | AW29: =SUM(AW26:AW28) | ... BA29: =SUM(BA26:BA28) | BB29: =BA29
B31: Plan Partner — Segmento C | H31: La cartera del canal es un stock, no un flujo: cada partner gestiona una cantidad finita de clientes. Modelarlo como altas mensuales perpetuas haría crecer el canal sin techo.
A32: PLAN PARTNER | B32: Partners activos | C32: =ROUND(Hipótesis!$C$36*1/12,0) | D32: =ROUND(Hipótesis!$C$36*2/12,0) | E32: =ROUND(Hipótesis!$C$36*3/12,0) | F32: =ROUND(Hipótesis!$C$36*4/12,0) | G32: =ROUND(Hipótesis!$C$36*5/12,0) | H32: =ROUND(Hipótesis!$C$36*6/12,0) | I32: =ROUND(Hipótesis!$C$36*7/12,0) | J32: =ROUND(Hipótesis!$C$36*8/12,0) | K32: =ROUND(Hipótesis!$C$36*9/12,0) | L32: =ROUND(Hipótesis!$C$36*10/12,0) | M32: =ROUND(Hipótesis!$C$36*11/12,0) | N32: =ROUND(Hipótesis!$C$36*12/12,0) | O32: =N32 | P32: =ROUND(Hipótesis!$C$36+(Hipótesis!$D$36-Hipótesis!$C$36)*1/12,0) | Q32: =ROUND(Hipótesis!$C$36+(Hipótesis!$D$36-Hipótesis!$C$36)*2/12,0) | R32: =ROUND(Hipótesis!$C$36+(Hipótesis!$D$36-Hipótesis!$C$36)*3/12,0) | S32: =ROUND(Hipótesis!$C$36+(Hipótesis!$D$36-Hipótesis!$C$36)*4/12,0) | T32: =ROUND(Hipótesis!$C$36+(Hipótesis!$D$36-Hipótesis!$C$36)*5/12,0) | U32: =ROUND(Hipótesis!$C$36+(Hipótesis!$D$36-Hipótesis!$C$36)*6/12,0) | V32: =ROUND(Hipótesis!$C$36+(Hipótesis!$D$36-Hipótesis!$C$36)*7/12,0) | W32: =ROUND(Hipótesis!$C$36+(Hipótesis!$D$36-Hipótesis!$C$36)*8/12,0) | X32: =ROUND(Hipótesis!$C$36+(Hipótesis!$D$36-Hipótesis!$C$36)*9/12,0) | Y32: =ROUND(Hipótesis!$C$36+(Hipótesis!$D$36-Hipótesis!$C$36)*10/12,0) | Z32: =ROUND(Hipótesis!$C$36+(Hipótesis!$D$36-Hipótesis!$C$36)*11/12,0) | AA32: =ROUND(Hipótesis!$C$36+(Hipótesis!$D$36-Hipótesis!$C$36)*12/12,0) | AB32: =AA32 | AC32: =ROUND(Hipótesis!$D$36+(Hipótesis!$E$36-Hipótesis!$D$36)*1/12,0) | AD32: =ROUND(Hipótesis!$D$36+(Hipótesis!$E$36-Hipótesis!$D$36)*2/12,0) | AE32: =ROUND(Hipótesis!$D$36+(Hipótesis!$E$36-Hipótesis!$D$36)*3/12,0) | AF32: =ROUND(Hipótesis!$D$36+(Hipótesis!$E$36-Hipótesis!$D$36)*4/12,0) | AG32: =ROUND(Hipótesis!$D$36+(Hipótesis!$E$36-Hipótesis!$D$36)*5/12,0) | AH32: =ROUND(Hipótesis!$D$36+(Hipótesis!$E$36-Hipótesis!$D$36)*6/12,0) | AI32: =ROUND(Hipótesis!$D$36+(Hipótesis!$E$36-Hipótesis!$D$36)*7/12,0) | AJ32: =ROUND(Hipótesis!$D$36+(Hipótesis!$E$36-Hipótesis!$D$36)*8/12,0) | AK32: =ROUND(Hipótesis!$D$36+(Hipótesis!$E$36-Hipótesis!$D$36)*9/12,0) | AL32: =ROUND(Hipótesis!$D$36+(Hipótesis!$E$36-Hipótesis!$D$36)*10/12,0) | AM32: =ROUND(Hipótesis!$D$36+(Hipótesis!$E$36-Hipótesis!$D$36)*11/12,0) | AN32: =ROUND(Hipótesis!$D$36+(Hipótesis!$E$36-Hipótesis!$D$36)*12/12,0) | AO32: =AN32 | AP32: =ROUND(Hipótesis!$E$36+(Hipótesis!$F$36-Hipótesis!$E$36)*1/12,0) | AQ32: =ROUND(Hipótesis!$E$36+(Hipótesis!$F$36-Hipótesis!$E$36)*2/12,0) | AR32: =ROUND(Hipótesis!$E$36+(Hipótesis!$F$36-Hipótesis!$E$36)*3/12,0) | AS32: =ROUND(Hipótesis!$E$36+(Hipótesis!$F$36-Hipótesis!$E$36)*4/12,0) | AT32: =ROUND(Hipótesis!$E$36+(Hipótesis!$F$36-Hipótesis!$E$36)*5/12,0) | AU32: =ROUND(Hipótesis!$E$36+(Hipótesis!$F$36-Hipótesis!$E$36)*6/12,0) | AV32: =ROUND(Hipótesis!$E$36+(Hipótesis!$F$36-Hipótesis!$E$36)*7/12,0) | AW32: =ROUND(Hipótesis!$E$36+(Hipótesis!$F$36-Hipótesis!$E$36)*8/12,0) | AX32: =ROUND(Hipótesis!$E$36+(Hipótesis!$F$36-Hipótesis!$E$36)*9/12,0) | AY32: =ROUND(Hipótesis!$E$36+(Hipótesis!$F$36-Hipótesis!$E$36)*10/12,0) | AZ32: =ROUND(Hipótesis!$E$36+(Hipótesis!$F$36-Hipótesis!$E$36)*11/12,0) | BA32: =ROUND(Hipótesis!$E$36+(Hipótesis!$F$36-Hipótesis!$E$36)*12/12,0) | BB32: =BA32
B33: Clientes gestionados por el canal | C33: =IF(1<Hipótesis!$C$35,0,C32*Hipótesis!$C$37) | D33: =IF(2<Hipótesis!$C$35,0,D32*Hipótesis!$C$37) | E33: =IF(3<Hipótesis!$C$35,0,E32*Hipótesis!$C$37) | F33: =IF(4<Hipótesis!$C$35,0,F32*Hipótesis!$C$37) | G33: =IF(5<Hipótesis!$C$35,0,G32*Hipótesis!$C$37) | H33: =IF(6<Hipótesis!$C$35,0,H32*Hipótesis!$C$37) | I33: =IF(7<Hipótesis!$C$35,0,I32*Hipótesis!$C$37) | J33: =IF(8<Hipótesis!$C$35,0,J32*Hipótesis!$C$37) | K33: =IF(9<Hipótesis!$C$35,0,K32*Hipótesis!$C$37) | L33: =IF(10<Hipótesis!$C$35,0,L32*Hipótesis!$C$37) | M33: =IF(11<Hipótesis!$C$35,0,M32*Hipótesis!$C$37) | N33: =IF(12<Hipótesis!$C$35,0,N32*Hipótesis!$C$37) | O33: =N33 | P33: =IF(13<Hipótesis!$C$35,0,P32*Hipótesis!$D$37) | Q33: =IF(14<Hipótesis!$C$35,0,Q32*Hipótesis!$D$37) | R33: =IF(15<Hipótesis!$C$35,0,R32*Hipótesis!$D$37) | S33: =IF(16<Hipótesis!$C$35,0,S32*Hipótesis!$D$37) | T33: =IF(17<Hipótesis!$C$35,0,T32*Hipótesis!$D$37) | U33: =IF(18<Hipótesis!$C$35,0,U32*Hipótesis!$D$37) | V33: =IF(19<Hipótesis!$C$35,0,V32*Hipótesis!$D$37) | W33: =IF(20<Hipótesis!$C$35,0,W32*Hipótesis!$D$37) | X33: =IF(21<Hipótesis!$C$35,0,X32*Hipótesis!$D$37) | Y33: =IF(22<Hipótesis!$C$35,0,Y32*Hipótesis!$D$37) | Z33: =IF(23<Hipótesis!$C$35,0,Z32*Hipótesis!$D$37) | AA33: =IF(24<Hipótesis!$C$35,0,AA32*Hipótesis!$D$37) | AB33: =AA33 | AC33: =IF(25<Hipótesis!$C$35,0,AC32*Hipótesis!$E$37) | AD33: =IF(26<Hipótesis!$C$35,0,AD32*Hipótesis!$E$37) | AE33: =IF(27<Hipótesis!$C$35,0,AE32*Hipótesis!$E$37) | AF33: =IF(28<Hipótesis!$C$35,0,AF32*Hipótesis!$E$37) | AG33: =IF(29<Hipótesis!$C$35,0,AG32*Hipótesis!$E$37) | AH33: =IF(30<Hipótesis!$C$35,0,AH32*Hipótesis!$E$37) | AI33: =IF(31<Hipótesis!$C$35,0,AI32*Hipótesis!$E$37) | AJ33: =IF(32<Hipótesis!$C$35,0,AJ32*Hipótesis!$E$37) | AK33: =IF(33<Hipótesis!$C$35,0,AK32*Hipótesis!$E$37) | AL33: =IF(34<Hipótesis!$C$35,0,AL32*Hipótesis!$E$37) | AM33: =IF(35<Hipótesis!$C$35,0,AM32*Hipótesis!$E$37) | AN33: =IF(36<Hipótesis!$C$35,0,AN32*Hipótesis!$E$37) | AO33: =AN33 | AP33: =IF(37<Hipótesis!$C$35,0,AP32*Hipótesis!$F$37) | AQ33: =IF(38<Hipótesis!$C$35,0,AQ32*Hipótesis!$F$37) | AR33: =IF(39<Hipótesis!$C$35,0,AR32*Hipótesis!$F$37) | AS33: =IF(40<Hipótesis!$C$35,0,AS32*Hipótesis!$F$37) | AT33: =IF(41<Hipótesis!$C$35,0,AT32*Hipótesis!$F$37) | AU33: =IF(42<Hipótesis!$C$35,0,AU32*Hipótesis!$F$37) | AV33: =IF(43<Hipótesis!$C$35,0,AV32*Hipótesis!$F$37) | AW33: =IF(44<Hipótesis!$C$35,0,AW32*Hipótesis!$F$37) | AX33: =IF(45<Hipótesis!$C$35,0,AX32*Hipótesis!$F$37) | AY33: =IF(46<Hipótesis!$C$35,0,AY32*Hipótesis!$F$37) | AZ33: =IF(47<Hipótesis!$C$35,0,AZ32*Hipótesis!$F$37) | BA33: =IF(48<Hipótesis!$C$35,0,BA32*Hipótesis!$F$37) | BB33: =BA33
B35: Consolidado
A36: TOTAL | B36: Clientes pagos activos | C36: =C22+C29+C33 | D36: =D22+D29+D33 | E36: =E22+E29+E33 | F36: =F22+F29+F33 | G36: =G22+G29+G33 | H36: =H22+H29+H33 | I36: =I22+I29+I33 | J36: =J22+J29+J33 | ... N36: =N22+N29+N33 | O36: =N36 | P36: =P22+P29+P33 | Q36: =Q22+Q29+Q33 | R36: =R22+R29+R33 | S36: =S22+S29+S33 | T36: =T22+T29+T33 | U36: =U22+U29+U33 | V36: =V22+V29+V33 | W36: =W22+W29+W33 | ... AA36: =AA22+AA29+AA33 | AB36: =AA36 | AC36: =AC22+AC29+AC33 | AD36: =AD22+AD29+AD33 | AE36: =AE22+AE29+AE33 | AF36: =AF22+AF29+AF33 | AG36: =AG22+AG29+AG33 | AH36: =AH22+AH29+AH33 | AI36: =AI22+AI29+AI33 | AJ36: =AJ22+AJ29+AJ33 | ... AN36: =AN22+AN29+AN33 | AO36: =AN36 | AP36: =AP22+AP29+AP33 | AQ36: =AQ22+AQ29+AQ33 | AR36: =AR22+AR29+AR33 | AS36: =AS22+AS29+AS33 | AT36: =AT22+AT29+AT33 | AU36: =AU22+AU29+AU33 | AV36: =AV22+AV29+AV33 | AW36: =AW22+AW29+AW33 | ... BA36: =BA22+BA29+BA33 | BB36: =BA36
B37: Equipos administrados | C37: =C22*Hipótesis!$C$41+C29*Hipótesis!$C$42+C33*Hipótesis!$C$43 | D37: =D22*Hipótesis!$C$41+D29*Hipótesis!$C$42+D33*Hipótesis!$C$43 | E37: =E22*Hipótesis!$C$41+E29*Hipótesis!$C$42+E33*Hipótesis!$C$43 | F37: =F22*Hipótesis!$C$41+F29*Hipótesis!$C$42+F33*Hipótesis!$C$43 | G37: =G22*Hipótesis!$C$41+G29*Hipótesis!$C$42+G33*Hipótesis!$C$43 | H37: =H22*Hipótesis!$C$41+H29*Hipótesis!$C$42+H33*Hipótesis!$C$43 | I37: =I22*Hipótesis!$C$41+I29*Hipótesis!$C$42+I33*Hipótesis!$C$43 | J37: =J22*Hipótesis!$C$41+J29*Hipótesis!$C$42+J33*Hipótesis!$C$43 | ... N37: =N22*Hipótesis!$C$41+N29*Hipótesis!$C$42+N33*Hipótesis!$C$43 | O37: =N37 | P37: =P22*Hipótesis!$D$41+P29*Hipótesis!$D$42+P33*Hipótesis!$D$43 | Q37: =Q22*Hipótesis!$D$41+Q29*Hipótesis!$D$42+Q33*Hipótesis!$D$43 | R37: =R22*Hipótesis!$D$41+R29*Hipótesis!$D$42+R33*Hipótesis!$D$43 | S37: =S22*Hipótesis!$D$41+S29*Hipótesis!$D$42+S33*Hipótesis!$D$43 | T37: =T22*Hipótesis!$D$41+T29*Hipótesis!$D$42+T33*Hipótesis!$D$43 | U37: =U22*Hipótesis!$D$41+U29*Hipótesis!$D$42+U33*Hipótesis!$D$43 | V37: =V22*Hipótesis!$D$41+V29*Hipótesis!$D$42+V33*Hipótesis!$D$43 | W37: =W22*Hipótesis!$D$41+W29*Hipótesis!$D$42+W33*Hipótesis!$D$43 | ... AA37: =AA22*Hipótesis!$D$41+AA29*Hipótesis!$D$42+AA33*Hipótesis!$D$43 | AB37: =AA37 | AC37: =AC22*Hipótesis!$E$41+AC29*Hipótesis!$E$42+AC33*Hipótesis!$E$43 | AD37: =AD22*Hipótesis!$E$41+AD29*Hipótesis!$E$42+AD33*Hipótesis!$E$43 | AE37: =AE22*Hipótesis!$E$41+AE29*Hipótesis!$E$42+AE33*Hipótesis!$E$43 | AF37: =AF22*Hipótesis!$E$41+AF29*Hipótesis!$E$42+AF33*Hipótesis!$E$43 | AG37: =AG22*Hipótesis!$E$41+AG29*Hipótesis!$E$42+AG33*Hipótesis!$E$43 | AH37: =AH22*Hipótesis!$E$41+AH29*Hipótesis!$E$42+AH33*Hipótesis!$E$43 | AI37: =AI22*Hipótesis!$E$41+AI29*Hipótesis!$E$42+AI33*Hipótesis!$E$43 | AJ37: =AJ22*Hipótesis!$E$41+AJ29*Hipótesis!$E$42+AJ33*Hipótesis!$E$43 | ... AN37: =AN22*Hipótesis!$E$41+AN29*Hipótesis!$E$42+AN33*Hipótesis!$E$43 | AO37: =AN37 | AP37: =AP22*Hipótesis!$F$41+AP29*Hipótesis!$F$42+AP33*Hipótesis!$F$43 | AQ37: =AQ22*Hipótesis!$F$41+AQ29*Hipótesis!$F$42+AQ33*Hipótesis!$F$43 | AR37: =AR22*Hipótesis!$F$41+AR29*Hipótesis!$F$42+AR33*Hipótesis!$F$43 | AS37: =AS22*Hipótesis!$F$41+AS29*Hipótesis!$F$42+AS33*Hipótesis!$F$43 | AT37: =AT22*Hipótesis!$F$41+AT29*Hipótesis!$F$42+AT33*Hipótesis!$F$43 | AU37: =AU22*Hipótesis!$F$41+AU29*Hipótesis!$F$42+AU33*Hipótesis!$F$43 | AV37: =AV22*Hipótesis!$F$41+AV29*Hipótesis!$F$42+AV33*Hipótesis!$F$43 | AW37: =AW22*Hipótesis!$F$41+AW29*Hipótesis!$F$42+AW33*Hipótesis!$F$43 | ... BA37: =BA22*Hipótesis!$F$41+BA29*Hipótesis!$F$42+BA33*Hipótesis!$F$43 | BB37: =BA37
B39: Verificación contra las metas del documento (5.3.3)
C40: Proyectado | D40: Meta | E40: Desvío
B41: Clientes pagos al mes 8 (Etapa E2) | C41: =J36 | D41: 10 | E41: =C41/D41-1
B42: Clientes pagos al mes 12 (Etapa E3) | C42: =N36 | D42: 25 | E42: =C42/D42-1
B43: Equipos administrados al mes 12 | C43: =N37 | D43: 1000 | E43: =C43/D43-1

Sheet Modelo de ingresos
A1: « Inicio
B2: MODELO DE INGRESOS
B3: Facturación por línea: abono de la base activa más los equipos que exceden lo que incluye cada plan. Los precios se actualizan una vez por año según el supuesto de aumento de lista.
C7: 2027 | P7: 2028 | AC7: 2029 | AP7: 2030
C8: Ene | D8: Feb | E8: Mar | F8: Abr | G8: May | H8: Jun | I8: Jul | J8: Ago | K8: Sep | L8: Oct | M8: Nov | N8: Dic | O8: Total 2027 | P8: Ene | Q8: Feb | R8: Mar | S8: Abr | T8: May | U8: Jun | V8: Jul | W8: Ago | X8: Sep | Y8: Oct | Z8: Nov | AA8: Dic | AB8: Total 2028 | AC8: Ene | AD8: Feb | AE8: Mar | AF8: Abr | AG8: May | AH8: Jun | AI8: Jul | AJ8: Ago | AK8: Sep | AL8: Oct | AM8: Nov | AN8: Dic | AO8: Total 2029 | AP8: Ene | AQ8: Feb | AR8: Mar | AS8: Abr | AT8: May | AU8: Jun | AV8: Jul | AW8: Ago | AX8: Sep | AY8: Oct | AZ8: Nov | BA8: Dic | BB8: Total 2030
B10: Plan Inicial
A11: PLAN INICIAL | B11: Ingreso por abono | C11: ='Proyección de ventas'!C22*Planes!$D$7*1 | D11: ='Proyección de ventas'!D22*Planes!$D$7*1 | E11: ='Proyección de ventas'!E22*Planes!$D$7*1 | F11: ='Proyección de ventas'!F22*Planes!$D$7*1 | G11: ='Proyección de ventas'!G22*Planes!$D$7*1 | H11: ='Proyección de ventas'!H22*Planes!$D$7*1 | I11: ='Proyección de ventas'!I22*Planes!$D$7*1 | J11: ='Proyección de ventas'!J22*Planes!$D$7*1 | ... N11: ='Proyección de ventas'!N22*Planes!$D$7*1 | O11: =SUM(C11:N11) | P11: ='Proyección de ventas'!P22*Planes!$D$7*(1+Hipótesis!$D$11) | Q11: ='Proyección de ventas'!Q22*Planes!$D$7*(1+Hipótesis!$D$11) | R11: ='Proyección de ventas'!R22*Planes!$D$7*(1+Hipótesis!$D$11) | S11: ='Proyección de ventas'!S22*Planes!$D$7*(1+Hipótesis!$D$11) | T11: ='Proyección de ventas'!T22*Planes!$D$7*(1+Hipótesis!$D$11) | U11: ='Proyección de ventas'!U22*Planes!$D$7*(1+Hipótesis!$D$11) | V11: ='Proyección de ventas'!V22*Planes!$D$7*(1+Hipótesis!$D$11) | W11: ='Proyección de ventas'!W22*Planes!$D$7*(1+Hipótesis!$D$11) | ... AA11: ='Proyección de ventas'!AA22*Planes!$D$7*(1+Hipótesis!$D$11) | AB11: =SUM(P11:AA11) | AC11: ='Proyección de ventas'!AC22*Planes!$D$7*(1+Hipótesis!$D$11)*(1+Hipótesis!$E$11) | AD11: ='Proyección de ventas'!AD22*Planes!$D$7*(1+Hipótesis!$D$11)*(1+Hipótesis!$E$11) | AE11: ='Proyección de ventas'!AE22*Planes!$D$7*(1+Hipótesis!$D$11)*(1+Hipótesis!$E$11) | AF11: ='Proyección de ventas'!AF22*Planes!$D$7*(1+Hipótesis!$D$11)*(1+Hipótesis!$E$11) | AG11: ='Proyección de ventas'!AG22*Planes!$D$7*(1+Hipótesis!$D$11)*(1+Hipótesis!$E$11) | AH11: ='Proyección de ventas'!AH22*Planes!$D$7*(1+Hipótesis!$D$11)*(1+Hipótesis!$E$11) | AI11: ='Proyección de ventas'!AI22*Planes!$D$7*(1+Hipótesis!$D$11)*(1+Hipótesis!$E$11) | AJ11: ='Proyección de ventas'!AJ22*Planes!$D$7*(1+Hipótesis!$D$11)*(1+Hipótesis!$E$11) | ... AN11: ='Proyección de ventas'!AN22*Planes!$D$7*(1+Hipótesis!$D$11)*(1+Hipótesis!$E$11) | AO11: =SUM(AC11:AN11) | AP11: ='Proyección de ventas'!AP22*Planes!$D$7*(1+Hipótesis!$D$11)*(1+Hipótesis!$E$11)*(1+Hipótesis!$F$11) | AQ11: ='Proyección de ventas'!AQ22*Planes!$D$7*(1+Hipótesis!$D$11)*(1+Hipótesis!$E$11)*(1+Hipótesis!$F$11) | AR11: ='Proyección de ventas'!AR22*Planes!$D$7*(1+Hipótesis!$D$11)*(1+Hipótesis!$E$11)*(1+Hipótesis!$F$11) | AS11: ='Proyección de ventas'!AS22*Planes!$D$7*(1+Hipótesis!$D$11)*(1+Hipótesis!$E$11)*(1+Hipótesis!$F$11) | AT11: ='Proyección de ventas'!AT22*Planes!$D$7*(1+Hipótesis!$D$11)*(1+Hipótesis!$E$11)*(1+Hipótesis!$F$11) | AU11: ='Proyección de ventas'!AU22*Planes!$D$7*(1+Hipótesis!$D$11)*(1+Hipótesis!$E$11)*(1+Hipótesis!$F$11) | AV11: ='Proyección de ventas'!AV22*Planes!$D$7*(1+Hipótesis!$D$11)*(1+Hipótesis!$E$11)*(1+Hipótesis!$F$11) | AW11: ='Proyección de ventas'!AW22*Planes!$D$7*(1+Hipótesis!$D$11)*(1+Hipótesis!$E$11)*(1+Hipótesis!$F$11) | ... BA11: ='Proyección de ventas'!BA22*Planes!$D$7*(1+Hipótesis!$D$11)*(1+Hipótesis!$E$11)*(1+Hipótesis!$F$11) | BB11: =SUM(AP11:BA11)
B12: Ingreso por equipos adicionales | C12: ='Proyección de ventas'!C22*MAX(0,Hipótesis!$C$41-Planes!$E$7)*Planes!$F$7*1 | D12: ='Proyección de ventas'!D22*MAX(0,Hipótesis!$C$41-Planes!$E$7)*Planes!$F$7*1 | E12: ='Proyección de ventas'!E22*MAX(0,Hipótesis!$C$41-Planes!$E$7)*Planes!$F$7*1 | F12: ='Proyección de ventas'!F22*MAX(0,Hipótesis!$C$41-Planes!$E$7)*Planes!$F$7*1 | G12: ='Proyección de ventas'!G22*MAX(0,Hipótesis!$C$41-Planes!$E$7)*Planes!$F$7*1 | H12: ='Proyección de ventas'!H22*MAX(0,Hipótesis!$C$41-Planes!$E$7)*Planes!$F$7*1 | I12: ='Proyección de ventas'!I22*MAX(0,Hipótesis!$C$41-Planes!$E$7)*Planes!$F$7*1 | J12: ='Proyección de ventas'!J22*MAX(0,Hipótesis!$C$41-Planes!$E$7)*Planes!$F$7*1 | ... N12: ='Proyección de ventas'!N22*MAX(0,Hipótesis!$C$41-Planes!$E$7)*Planes!$F$7*1 | O12: =SUM(C12:N12) | P12: ='Proyección de ventas'!P22*MAX(0,Hipótesis!$D$41-Planes!$E$7)*Planes!$F$7*(1+Hipótesis!$D$11) | Q12: ='Proyección de ventas'!Q22*MAX(0,Hipótesis!$D$41-Planes!$E$7)*Planes!$F$7*(1+Hipótesis!$D$11) | R12: ='Proyección de ventas'!R22*MAX(0,Hipótesis!$D$41-Planes!$E$7)*Planes!$F$7*(1+Hipótesis!$D$11) | S12: ='Proyección de ventas'!S22*MAX(0,Hipótesis!$D$41-Planes!$E$7)*Planes!$F$7*(1+Hipótesis!$D$11) | T12: ='Proyección de ventas'!T22*MAX(0,Hipótesis!$D$41-Planes!$E$7)*Planes!$F$7*(1+Hipótesis!$D$11) | U12: ='Proyección de ventas'!U22*MAX(0,Hipótesis!$D$41-Planes!$E$7)*Planes!$F$7*(1+Hipótesis!$D$11) | V12: ='Proyección de ventas'!V22*MAX(0,Hipótesis!$D$41-Planes!$E$7)*Planes!$F$7*(1+Hipótesis!$D$11) | W12: ='Proyección de ventas'!W22*MAX(0,Hipótesis!$D$41-Planes!$E$7)*Planes!$F$7*(1+Hipótesis!$D$11) | ... AA12: ='Proyección de ventas'!AA22*MAX(0,Hipótesis!$D$41-Planes!$E$7)*Planes!$F$7*(1+Hipótesis!$D$11) | AB12: =SUM(P12:AA12) | AC12: ='Proyección de ventas'!AC22*MAX(0,Hipótesis!$E$41-Planes!$E$7)*Planes!$F$7*(1+Hipótesis!$D$11)*(1+Hipótesis!$E$11) | AD12: ='Proyección de ventas'!AD22*MAX(0,Hipótesis!$E$41-Planes!$E$7)*Planes!$F$7*(1+Hipótesis!$D$11)*(1+Hipótesis!$E$11) | AE12: ='Proyección de ventas'!AE22*MAX(0,Hipótesis!$E$41-Planes!$E$7)*Planes!$F$7*(1+Hipótesis!$D$11)*(1+Hipótesis!$E$11) | AF12: ='Proyección de ventas'!AF22*MAX(0,Hipótesis!$E$41-Planes!$E$7)*Planes!$F$7*(1+Hipótesis!$D$11)*(1+Hipótesis!$E$11) | AG12: ='Proyección de ventas'!AG22*MAX(0,Hipótesis!$E$41-Planes!$E$7)*Planes!$F$7*(1+Hipótesis!$D$11)*(1+Hipótesis!$E$11) | AH12: ='Proyección de ventas'!AH22*MAX(0,Hipótesis!$E$41-Planes!$E$7)*Planes!$F$7*(1+Hipótesis!$D$11)*(1+Hipótesis!$E$11) | AI12: ='Proyección de ventas'!AI22*MAX(0,Hipótesis!$E$41-Planes!$E$7)*Planes!$F$7*(1+Hipótesis!$D$11)*(1+Hipótesis!$E$11) | AJ12: ='Proyección de ventas'!AJ22*MAX(0,Hipótesis!$E$41-Planes!$E$7)*Planes!$F$7*(1+Hipótesis!$D$11)*(1+Hipótesis!$E$11) | ... AN12: ='Proyección de ventas'!AN22*MAX(0,Hipótesis!$E$41-Planes!$E$7)*Planes!$F$7*(1+Hipótesis!$D$11)*(1+Hipótesis!$E$11) | AO12: =SUM(AC12:AN12) | AP12: ='Proyección de ventas'!AP22*MAX(0,Hipótesis!$F$41-Planes!$E$7)*Planes!$F$7*(1+Hipótesis!$D$11)*(1+Hipótesis!$E$11)*(1+Hipótesis!$F$11) | AQ12: ='Proyección de ventas'!AQ22*MAX(0,Hipótesis!$F$41-Planes!$E$7)*Planes!$F$7*(1+Hipótesis!$D$11)*(1+Hipótesis!$E$11)*(1+Hipótesis!$F$11) | AR12: ='Proyección de ventas'!AR22*MAX(0,Hipótesis!$F$41-Planes!$E$7)*Planes!$F$7*(1+Hipótesis!$D$11)*(1+Hipótesis!$E$11)*(1+Hipótesis!$F$11) | AS12: ='Proyección de ventas'!AS22*MAX(0,Hipótesis!$F$41-Planes!$E$7)*Planes!$F$7*(1+Hipótesis!$D$11)*(1+Hipótesis!$E$11)*(1+Hipótesis!$F$11) | AT12: ='Proyección de ventas'!AT22*MAX(0,Hipótesis!$F$41-Planes!$E$7)*Planes!$F$7*(1+Hipótesis!$D$11)*(1+Hipótesis!$E$11)*(1+Hipótesis!$F$11) | AU12: ='Proyección de ventas'!AU22*MAX(0,Hipótesis!$F$41-Planes!$E$7)*Planes!$F$7*(1+Hipótesis!$D$11)*(1+Hipótesis!$E$11)*(1+Hipótesis!$F$11) | AV12: ='Proyección de ventas'!AV22*MAX(0,Hipótesis!$F$41-Planes!$E$7)*Planes!$F$7*(1+Hipótesis!$D$11)*(1+Hipótesis!$E$11)*(1+Hipótesis!$F$11) | AW12: ='Proyección de ventas'!AW22*MAX(0,Hipótesis!$F$41-Planes!$E$7)*Planes!$F$7*(1+Hipótesis!$D$11)*(1+Hipótesis!$E$11)*(1+Hipótesis!$F$11) | ... BA12: ='Proyección de ventas'!BA22*MAX(0,Hipótesis!$F$41-Planes!$E$7)*Planes!$F$7*(1+Hipótesis!$D$11)*(1+Hipótesis!$E$11)*(1+Hipótesis!$F$11) | BB12: =SUM(AP12:BA12)
B13: Total de la línea | C13: =C11+C12 | D13: =D11+D12 | E13: =E11+E12 | F13: =F11+F12 | G13: =G11+G12 | H13: =H11+H12 | I13: =I11+I12 | J13: =J11+J12 | ... N13: =N11+N12 | O13: =SUM(C13:N13) | P13: =P11+P12 | Q13: =Q11+Q12 | R13: =R11+R12 | S13: =S11+S12 | T13: =T11+T12 | U13: =U11+U12 | V13: =V11+V12 | W13: =W11+W12 | ... AA13: =AA11+AA12 | AB13: =SUM(P13:AA13) | AC13: =AC11+AC12 | AD13: =AD11+AD12 | AE13: =AE11+AE12 | AF13: =AF11+AF12 | AG13: =AG11+AG12 | AH13: =AH11+AH12 | AI13: =AI11+AI12 | AJ13: =AJ11+AJ12 | ... AN13: =AN11+AN12 | AO13: =SUM(AC13:AN13) | AP13: =AP11+AP12 | AQ13: =AQ11+AQ12 | AR13: =AR11+AR12 | AS13: =AS11+AS12 | AT13: =AT11+AT12 | AU13: =AU11+AU12 | AV13: =AV11+AV12 | AW13: =AW11+AW12 | ... BA13: =BA11+BA12 | BB13: =SUM(AP13:BA13)
B15: Plan Estándar
A16: PLAN ESTÁNDAR | B16: Ingreso por abono | C16: ='Proyección de ventas'!C29*Planes!$D$8*1 | D16: ='Proyección de ventas'!D29*Planes!$D$8*1 | E16: ='Proyección de ventas'!E29*Planes!$D$8*1 | F16: ='Proyección de ventas'!F29*Planes!$D$8*1 | G16: ='Proyección de ventas'!G29*Planes!$D$8*1 | H16: ='Proyección de ventas'!H29*Planes!$D$8*1 | I16: ='Proyección de ventas'!I29*Planes!$D$8*1 | J16: ='Proyección de ventas'!J29*Planes!$D$8*1 | ... N16: ='Proyección de ventas'!N29*Planes!$D$8*1 | O16: =SUM(C16:N16) | P16: ='Proyección de ventas'!P29*Planes!$D$8*(1+Hipótesis!$D$11) | Q16: ='Proyección de ventas'!Q29*Planes!$D$8*(1+Hipótesis!$D$11) | R16: ='Proyección de ventas'!R29*Planes!$D$8*(1+Hipótesis!$D$11) | S16: ='Proyección de ventas'!S29*Planes!$D$8*(1+Hipótesis!$D$11) | T16: ='Proyección de ventas'!T29*Planes!$D$8*(1+Hipótesis!$D$11) | U16: ='Proyección de ventas'!U29*Planes!$D$8*(1+Hipótesis!$D$11) | V16: ='Proyección de ventas'!V29*Planes!$D$8*(1+Hipótesis!$D$11) | W16: ='Proyección de ventas'!W29*Planes!$D$8*(1+Hipótesis!$D$11) | ... AA16: ='Proyección de ventas'!AA29*Planes!$D$8*(1+Hipótesis!$D$11) | AB16: =SUM(P16:AA16) | AC16: ='Proyección de ventas'!AC29*Planes!$D$8*(1+Hipótesis!$D$11)*(1+Hipótesis!$E$11) | AD16: ='Proyección de ventas'!AD29*Planes!$D$8*(1+Hipótesis!$D$11)*(1+Hipótesis!$E$11) | AE16: ='Proyección de ventas'!AE29*Planes!$D$8*(1+Hipótesis!$D$11)*(1+Hipótesis!$E$11) | AF16: ='Proyección de ventas'!AF29*Planes!$D$8*(1+Hipótesis!$D$11)*(1+Hipótesis!$E$11) | AG16: ='Proyección de ventas'!AG29*Planes!$D$8*(1+Hipótesis!$D$11)*(1+Hipótesis!$E$11) | AH16: ='Proyección de ventas'!AH29*Planes!$D$8*(1+Hipótesis!$D$11)*(1+Hipótesis!$E$11) | AI16: ='Proyección de ventas'!AI29*Planes!$D$8*(1+Hipótesis!$D$11)*(1+Hipótesis!$E$11) | AJ16: ='Proyección de ventas'!AJ29*Planes!$D$8*(1+Hipótesis!$D$11)*(1+Hipótesis!$E$11) | ... AN16: ='Proyección de ventas'!AN29*Planes!$D$8*(1+Hipótesis!$D$11)*(1+Hipótesis!$E$11) | AO16: =SUM(AC16:AN16) | AP16: ='Proyección de ventas'!AP29*Planes!$D$8*(1+Hipótesis!$D$11)*(1+Hipótesis!$E$11)*(1+Hipótesis!$F$11) | AQ16: ='Proyección de ventas'!AQ29*Planes!$D$8*(1+Hipótesis!$D$11)*(1+Hipótesis!$E$11)*(1+Hipótesis!$F$11) | AR16: ='Proyección de ventas'!AR29*Planes!$D$8*(1+Hipótesis!$D$11)*(1+Hipótesis!$E$11)*(1+Hipótesis!$F$11) | AS16: ='Proyección de ventas'!AS29*Planes!$D$8*(1+Hipótesis!$D$11)*(1+Hipótesis!$E$11)*(1+Hipótesis!$F$11) | AT16: ='Proyección de ventas'!AT29*Planes!$D$8*(1+Hipótesis!$D$11)*(1+Hipótesis!$E$11)*(1+Hipótesis!$F$11) | AU16: ='Proyección de ventas'!AU29*Planes!$D$8*(1+Hipótesis!$D$11)*(1+Hipótesis!$E$11)*(1+Hipótesis!$F$11) | AV16: ='Proyección de ventas'!AV29*Planes!$D$8*(1+Hipótesis!$D$11)*(1+Hipótesis!$E$11)*(1+Hipótesis!$F$11) | AW16: ='Proyección de ventas'!AW29*Planes!$D$8*(1+Hipótesis!$D$11)*(1+Hipótesis!$E$11)*(1+Hipótesis!$F$11) | ... BA16: ='Proyección de ventas'!BA29*Planes!$D$8*(1+Hipótesis!$D$11)*(1+Hipótesis!$E$11)*(1+Hipótesis!$F$11) | BB16: =SUM(AP16:BA16)
B17: Ingreso por equipos adicionales | C17: ='Proyección de ventas'!C29*MAX(0,Hipótesis!$C$42-Planes!$E$8)*Planes!$F$8*1 | D17: ='Proyección de ventas'!D29*MAX(0,Hipótesis!$C$42-Planes!$E$8)*Planes!$F$8*1 | E17: ='Proyección de ventas'!E29*MAX(0,Hipótesis!$C$42-Planes!$E$8)*Planes!$F$8*1 | F17: ='Proyección de ventas'!F29*MAX(0,Hipótesis!$C$42-Planes!$E$8)*Planes!$F$8*1 | G17: ='Proyección de ventas'!G29*MAX(0,Hipótesis!$C$42-Planes!$E$8)*Planes!$F$8*1 | H17: ='Proyección de ventas'!H29*MAX(0,Hipótesis!$C$42-Planes!$E$8)*Planes!$F$8*1 | I17: ='Proyección de ventas'!I29*MAX(0,Hipótesis!$C$42-Planes!$E$8)*Planes!$F$8*1 | J17: ='Proyección de ventas'!J29*MAX(0,Hipótesis!$C$42-Planes!$E$8)*Planes!$F$8*1 | ... N17: ='Proyección de ventas'!N29*MAX(0,Hipótesis!$C$42-Planes!$E$8)*Planes!$F$8*1 | O17: =SUM(C17:N17) | P17: ='Proyección de ventas'!P29*MAX(0,Hipótesis!$D$42-Planes!$E$8)*Planes!$F$8*(1+Hipótesis!$D$11) | Q17: ='Proyección de ventas'!Q29*MAX(0,Hipótesis!$D$42-Planes!$E$8)*Planes!$F$8*(1+Hipótesis!$D$11) | R17: ='Proyección de ventas'!R29*MAX(0,Hipótesis!$D$42-Planes!$E$8)*Planes!$F$8*(1+Hipótesis!$D$11) | S17: ='Proyección de ventas'!S29*MAX(0,Hipótesis!$D$42-Planes!$E$8)*Planes!$F$8*(1+Hipótesis!$D$11) | T17: ='Proyección de ventas'!T29*MAX(0,Hipótesis!$D$42-Planes!$E$8)*Planes!$F$8*(1+Hipótesis!$D$11) | U17: ='Proyección de ventas'!U29*MAX(0,Hipótesis!$D$42-Planes!$E$8)*Planes!$F$8*(1+Hipótesis!$D$11) | V17: ='Proyección de ventas'!V29*MAX(0,Hipótesis!$D$42-Planes!$E$8)*Planes!$F$8*(1+Hipótesis!$D$11) | W17: ='Proyección de ventas'!W29*MAX(0,Hipótesis!$D$42-Planes!$E$8)*Planes!$F$8*(1+Hipótesis!$D$11) | ... AA17: ='Proyección de ventas'!AA29*MAX(0,Hipótesis!$D$42-Planes!$E$8)*Planes!$F$8*(1+Hipótesis!$D$11) | AB17: =SUM(P17:AA17) | AC17: ='Proyección de ventas'!AC29*MAX(0,Hipótesis!$E$42-Planes!$E$8)*Planes!$F$8*(1+Hipótesis!$D$11)*(1+Hipótesis!$E$11) | AD17: ='Proyección de ventas'!AD29*MAX(0,Hipótesis!$E$42-Planes!$E$8)*Planes!$F$8*(1+Hipótesis!$D$11)*(1+Hipótesis!$E$11) | AE17: ='Proyección de ventas'!AE29*MAX(0,Hipótesis!$E$42-Planes!$E$8)*Planes!$F$8*(1+Hipótesis!$D$11)*(1+Hipótesis!$E$11) | AF17: ='Proyección de ventas'!AF29*MAX(0,Hipótesis!$E$42-Planes!$E$8)*Planes!$F$8*(1+Hipótesis!$D$11)*(1+Hipótesis!$E$11) | AG17: ='Proyección de ventas'!AG29*MAX(0,Hipótesis!$E$42-Planes!$E$8)*Planes!$F$8*(1+Hipótesis!$D$11)*(1+Hipótesis!$E$11) | AH17: ='Proyección de ventas'!AH29*MAX(0,Hipótesis!$E$42-Planes!$E$8)*Planes!$F$8*(1+Hipótesis!$D$11)*(1+Hipótesis!$E$11) | AI17: ='Proyección de ventas'!AI29*MAX(0,Hipótesis!$E$42-Planes!$E$8)*Planes!$F$8*(1+Hipótesis!$D$11)*(1+Hipótesis!$E$11) | AJ17: ='Proyección de ventas'!AJ29*MAX(0,Hipótesis!$E$42-Planes!$E$8)*Planes!$F$8*(1+Hipótesis!$D$11)*(1+Hipótesis!$E$11) | ... AN17: ='Proyección de ventas'!AN29*MAX(0,Hipótesis!$E$42-Planes!$E$8)*Planes!$F$8*(1+Hipótesis!$D$11)*(1+Hipótesis!$E$11) | AO17: =SUM(AC17:AN17) | AP17: ='Proyección de ventas'!AP29*MAX(0,Hipótesis!$F$42-Planes!$E$8)*Planes!$F$8*(1+Hipótesis!$D$11)*(1+Hipótesis!$E$11)*(1+Hipótesis!$F$11) | AQ17: ='Proyección de ventas'!AQ29*MAX(0,Hipótesis!$F$42-Planes!$E$8)*Planes!$F$8*(1+Hipótesis!$D$11)*(1+Hipótesis!$E$11)*(1+Hipótesis!$F$11) | AR17: ='Proyección de ventas'!AR29*MAX(0,Hipótesis!$F$42-Planes!$E$8)*Planes!$F$8*(1+Hipótesis!$D$11)*(1+Hipótesis!$E$11)*(1+Hipótesis!$F$11) | AS17: ='Proyección de ventas'!AS29*MAX(0,Hipótesis!$F$42-Planes!$E$8)*Planes!$F$8*(1+Hipótesis!$D$11)*(1+Hipótesis!$E$11)*(1+Hipótesis!$F$11) | AT17: ='Proyección de ventas'!AT29*MAX(0,Hipótesis!$F$42-Planes!$E$8)*Planes!$F$8*(1+Hipótesis!$D$11)*(1+Hipótesis!$E$11)*(1+Hipótesis!$F$11) | AU17: ='Proyección de ventas'!AU29*MAX(0,Hipótesis!$F$42-Planes!$E$8)*Planes!$F$8*(1+Hipótesis!$D$11)*(1+Hipótesis!$E$11)*(1+Hipótesis!$F$11) | AV17: ='Proyección de ventas'!AV29*MAX(0,Hipótesis!$F$42-Planes!$E$8)*Planes!$F$8*(1+Hipótesis!$D$11)*(1+Hipótesis!$E$11)*(1+Hipótesis!$F$11) | AW17: ='Proyección de ventas'!AW29*MAX(0,Hipótesis!$F$42-Planes!$E$8)*Planes!$F$8*(1+Hipótesis!$D$11)*(1+Hipótesis!$E$11)*(1+Hipótesis!$F$11) | ... BA17: ='Proyección de ventas'!BA29*MAX(0,Hipótesis!$F$42-Planes!$E$8)*Planes!$F$8*(1+Hipótesis!$D$11)*(1+Hipótesis!$E$11)*(1+Hipótesis!$F$11) | BB17: =SUM(AP17:BA17)
B18: Total de la línea | C18: =C16+C17 | D18: =D16+D17 | E18: =E16+E17 | F18: =F16+F17 | G18: =G16+G17 | H18: =H16+H17 | I18: =I16+I17 | J18: =J16+J17 | ... N18: =N16+N17 | O18: =SUM(C18:N18) | P18: =P16+P17 | Q18: =Q16+Q17 | R18: =R16+R17 | S18: =S16+S17 | T18: =T16+T17 | U18: =U16+U17 | V18: =V16+V17 | W18: =W16+W17 | ... AA18: =AA16+AA17 | AB18: =SUM(P18:AA18) | AC18: =AC16+AC17 | AD18: =AD16+AD17 | AE18: =AE16+AE17 | AF18: =AF16+AF17 | AG18: =AG16+AG17 | AH18: =AH16+AH17 | AI18: =AI16+AI17 | AJ18: =AJ16+AJ17 | ... AN18: =AN16+AN17 | AO18: =SUM(AC18:AN18) | AP18: =AP16+AP17 | AQ18: =AQ16+AQ17 | AR18: =AR16+AR17 | AS18: =AS16+AS17 | AT18: =AT16+AT17 | AU18: =AU16+AU17 | AV18: =AV16+AV17 | AW18: =AW16+AW17 | ... BA18: =BA16+BA17 | BB18: =SUM(AP18:BA18)
B20: Plan Partner
A21: PLAN PARTNER | B21: Ingreso por abono | C21: ='Proyección de ventas'!C33*Planes!$D$9*1 | D21: ='Proyección de ventas'!D33*Planes!$D$9*1 | E21: ='Proyección de ventas'!E33*Planes!$D$9*1 | F21: ='Proyección de ventas'!F33*Planes!$D$9*1 | G21: ='Proyección de ventas'!G33*Planes!$D$9*1 | H21: ='Proyección de ventas'!H33*Planes!$D$9*1 | I21: ='Proyección de ventas'!I33*Planes!$D$9*1 | J21: ='Proyección de ventas'!J33*Planes!$D$9*1 | ... N21: ='Proyección de ventas'!N33*Planes!$D$9*1 | O21: =SUM(C21:N21) | P21: ='Proyección de ventas'!P33*Planes!$D$9*(1+Hipótesis!$D$11) | Q21: ='Proyección de ventas'!Q33*Planes!$D$9*(1+Hipótesis!$D$11) | R21: ='Proyección de ventas'!R33*Planes!$D$9*(1+Hipótesis!$D$11) | S21: ='Proyección de ventas'!S33*Planes!$D$9*(1+Hipótesis!$D$11) | T21: ='Proyección de ventas'!T33*Planes!$D$9*(1+Hipótesis!$D$11) | U21: ='Proyección de ventas'!U33*Planes!$D$9*(1+Hipótesis!$D$11) | V21: ='Proyección de ventas'!V33*Planes!$D$9*(1+Hipótesis!$D$11) | W21: ='Proyección de ventas'!W33*Planes!$D$9*(1+Hipótesis!$D$11) | ... AA21: ='Proyección de ventas'!AA33*Planes!$D$9*(1+Hipótesis!$D$11) | AB21: =SUM(P21:AA21) | AC21: ='Proyección de ventas'!AC33*Planes!$D$9*(1+Hipótesis!$D$11)*(1+Hipótesis!$E$11) | AD21: ='Proyección de ventas'!AD33*Planes!$D$9*(1+Hipótesis!$D$11)*(1+Hipótesis!$E$11) | AE21: ='Proyección de ventas'!AE33*Planes!$D$9*(1+Hipótesis!$D$11)*(1+Hipótesis!$E$11) | AF21: ='Proyección de ventas'!AF33*Planes!$D$9*(1+Hipótesis!$D$11)*(1+Hipótesis!$E$11) | AG21: ='Proyección de ventas'!AG33*Planes!$D$9*(1+Hipótesis!$D$11)*(1+Hipótesis!$E$11) | AH21: ='Proyección de ventas'!AH33*Planes!$D$9*(1+Hipótesis!$D$11)*(1+Hipótesis!$E$11) | AI21: ='Proyección de ventas'!AI33*Planes!$D$9*(1+Hipótesis!$D$11)*(1+Hipótesis!$E$11) | AJ21: ='Proyección de ventas'!AJ33*Planes!$D$9*(1+Hipótesis!$D$11)*(1+Hipótesis!$E$11) | ... AN21: ='Proyección de ventas'!AN33*Planes!$D$9*(1+Hipótesis!$D$11)*(1+Hipótesis!$E$11) | AO21: =SUM(AC21:AN21) | AP21: ='Proyección de ventas'!AP33*Planes!$D$9*(1+Hipótesis!$D$11)*(1+Hipótesis!$E$11)*(1+Hipótesis!$F$11) | AQ21: ='Proyección de ventas'!AQ33*Planes!$D$9*(1+Hipótesis!$D$11)*(1+Hipótesis!$E$11)*(1+Hipótesis!$F$11) | AR21: ='Proyección de ventas'!AR33*Planes!$D$9*(1+Hipótesis!$D$11)*(1+Hipótesis!$E$11)*(1+Hipótesis!$F$11) | AS21: ='Proyección de ventas'!AS33*Planes!$D$9*(1+Hipótesis!$D$11)*(1+Hipótesis!$E$11)*(1+Hipótesis!$F$11) | AT21: ='Proyección de ventas'!AT33*Planes!$D$9*(1+Hipótesis!$D$11)*(1+Hipótesis!$E$11)*(1+Hipótesis!$F$11) | AU21: ='Proyección de ventas'!AU33*Planes!$D$9*(1+Hipótesis!$D$11)*(1+Hipótesis!$E$11)*(1+Hipótesis!$F$11) | AV21: ='Proyección de ventas'!AV33*Planes!$D$9*(1+Hipótesis!$D$11)*(1+Hipótesis!$E$11)*(1+Hipótesis!$F$11) | AW21: ='Proyección de ventas'!AW33*Planes!$D$9*(1+Hipótesis!$D$11)*(1+Hipótesis!$E$11)*(1+Hipótesis!$F$11) | ... BA21: ='Proyección de ventas'!BA33*Planes!$D$9*(1+Hipótesis!$D$11)*(1+Hipótesis!$E$11)*(1+Hipótesis!$F$11) | BB21: =SUM(AP21:BA21)
